Workbook

Sheet AUTO (2)
E1: 선택하여 붙여 넣기 값
A2: 재 하 하 중 | E2: 변위량
A3: 시험 단계 | B3: 하 중 (kgf) | C3: 하중강도 (kN/㎡) | D3: 누계침하량 (mm) | E3: 좌 | F3: 우 | G3: 평균 (mm)
A4: 0 | B4: 0 | C4: 0 | D4: 0 | E4: 0 | F4: 0 | G4: =(E4+F4)/2 -> 0 | I4: 계수 | J4: 0.7 | K4: 0.7
A5: 1 | B5: 450 | C5: 35 | D5: =G5-G$4 -> 0.46 | E5: =ROUNDUP(E4+H5,3) -> 0.48 | F5: =ROUNDUP(F4+I5,3) -> 0.44 | G5: =IFERROR((E5+F5)/2," ") -> 0.46 | H5: =ROUNDUP(RAND()/J5/3,2) -> 0.48 | I5: =ROUNDUP(RAND()/K5/3,2) -> 0.44 | J5: =J4 -> 0.7 | K5: =K4 -> 0.7
A6: 2 | B6: 900 | C6: 70 | D6: =G6-G$4 -> 0.625 | E6: =ROUNDUP(E5+H6,3) -> 0.53 | F6: =ROUNDUP(F5+I6,3) -> 0.72 | G6: =IFERROR((E6+F6)/2," ") -> 0.625 | H6: =ROUNDUP(RAND()/J6/3,2) -> 0.05 | I6: =ROUNDUP(RAND()/K6/3,2) -> 0.28 | J6: =J5 -> 0.7 | K6: =K5 -> 0.7
A7: 3 | B7: 1350 | C7: 105 | D7: =G7-G$4 -> 0.855 | E7: =ROUNDUP(E6+H7,3) -> 0.98 | F7: =ROUNDUP(F6+I7,3) -> 0.73 | G7: =IFERROR((E7+F7)/2," ") -> 0.855 | H7: =ROUNDUP(RAND()/J7/3,2) -> 0.45 | I7: =ROUNDUP(RAND()/K7/3,2) -> 0.01 | J7: =J6 -> 0.7 | K7: =K6 -> 0.7
A8: 4 | B8: 1800 | C8: 140 | D8: =G8-G$4 -> 1.135 | E8: =ROUNDUP(E7+H8,3) -> 1.36 | F8: =ROUNDUP(F7+I8,3) -> 0.91 | G8: =IFERROR((E8+F8)/2," ") -> 1.135 | H8: =ROUNDUP(RAND()/J8/3,2) -> 0.38 | I8: =ROUNDUP(RAND()/K8/3,2) -> 0.18 | J8: =J7 -> 0.7 | K8: =K7 -> 0.7
A9: 5 | B9: 2250 | C9: 175 | D9: =G9-G$4 -> 1.32 | E9: =ROUNDUP(E8+H9,3) -> 1.41 | F9: =ROUNDUP(F8+I9,3) -> 1.23 | G9: =IFERROR((E9+F9)/2," ") -> 1.32 | H9: =ROUNDUP(RAND()/J9/3,2) -> 0.05 | I9: =ROUNDUP(RAND()/K9/3,2) -> 0.32 | J9: =J8 -> 0.7 | K9: =K8 -> 0.7
A10: 6 | B10: 2700 | C10: 210 | D10: =G10-G$4 -> 1.43 | E10: =ROUNDUP(E9+H10,3) -> 1.56 | F10: =ROUNDUP(F9+I10,3) -> 1.3 | G10: =IFERROR((E10+F10)/2," ") -> 1.43 | H10: =ROUNDUP(RAND()/J10/3,2) -> 0.15 | I10: =ROUNDUP(RAND()/K10/3,2) -> 0.07 | J10: =J4+0.6 -> 1.3 | K10: =K4+0.6 -> 1.3
A11: 7 | B11: 3140 | C11: 245 | D11: =G11-G$4 -> 1.55 | E11: =ROUNDUP(E10+H11,3) -> 1.71 | F11: =ROUNDUP(F10+I11,3) -> 1.39 | G11: =IFERROR((E11+F11)/2," ") -> 1.55 | H11: =ROUNDUP(RAND()/J11/3,2) -> 0.15 | I11: =ROUNDUP(RAND()/K11/3,2) -> 0.09 | J11: =J10 -> 1.3 | K11: =K10 -> 1.3
A12: 8 | B12: 3590 | C12: 280 | D12: =G12-G$4 -> 1.69 | E12: =ROUNDUP(E11+H12,3) -> 1.77 | F12: =ROUNDUP(F11+I12,3) -> 1.61 | G12: =IFERROR((E12+F12)/2," ") -> 1.69 | H12: =ROUNDUP(RAND()/J12/3,2) -> 0.06 | I12: =ROUNDUP(RAND()/K12/3,2) -> 0.22 | J12: =J11 -> 1.3 | K12: =K11 -> 1.3
A13: 9 | B13: 4040 | C13: 315 | D13: =G13-G$4 -> 1.805 | E13: =ROUNDUP(E12+H13,3) -> 1.89 | F13: =ROUNDUP(F12+I13,3) -> 1.72 | G13: =IFERROR((E13+F13)/2," ") -> 1.805 | H13: =ROUNDUP(RAND()/J13/3,2) -> 0.12 | I13: =ROUNDUP(RAND()/K13/3,2) -> 0.11 | J13: =J12 -> 1.3 | K13: =K12 -> 1.3
A14: 10 | B14: 4490 | C14: 350 | D14: =G14-G$4 -> 1.955 | E14: =ROUNDUP(E13+H14,3) -> 1.97 | F14: =ROUNDUP(F13+I14,3) -> 1.94 | G14: =IFERROR((E14+F14)/2," ") -> 1.955 | H14: =ROUNDUP(RAND()/J14/3,2) -> 0.08 | I14: =ROUNDUP(RAND()/K14/3,2) -> 0.22 | J14: =J13 -> 1.3 | K14: =K13 -> 1.3
A15: 11 | B15: 4940 | C15: 385 | D15: =G15-G$4 -> 2.085 | E15: =ROUNDUP(E14+H15,3) -> 2.04 | F15: =ROUNDUP(F14+I15,3) -> 2.13 | G15: =IFERROR((E15+F15)/2," ") -> 2.085 | H15: =ROUNDUP(RAND()/J15/3,2) -> 0.07 | I15: =ROUNDUP(RAND()/K15/3,2) -> 0.19 | J15: =J14 -> 1.3 | K15: =K14 -> 1.3
A16: 12 | B16: 5390 | C16: 420 | D16: =G16-G$4 -> 2.33 | E16: =ROUNDUP(E15+H16,3) -> 2.27 | F16: =ROUNDUP(F15+I16,3) -> 2.39 | G16: =IFERROR((E16+F16)/2," ") -> 2.33 | H16: =ROUNDUP(RAND()/J16/3,2) -> 0.23 | I16: =ROUNDUP(RAND()/K16/3,2) -> 0.26 | J16: =J15 -> 1.3 | K16: =K15 -> 1.3
A17: 13 | C17: 455 | D17: =G17-G$4 -> 2.445 | E17: =ROUNDUP(E16+H17,3) -> 2.46 | F17: =ROUNDUP(F16+I17,3) -> 2.43 | G17: =IFERROR((E17+F17)/2," ") -> 2.445 | H17: =ROUNDUP(RAND()/J17/3,2) -> 0.19 | I17: =ROUNDUP(RAND()/K17/3,2) -> 0.04 | J17: =J10+0.2 -> 1.5 | K17: =K10+0.2 -> 1.5
A18: 14 | C18: 490 | D18: =G18-G$4 -> 2.565 | E18: =ROUNDUP(E17+H18,3) -> 2.6 | F18: =ROUNDUP(F17+I18,3) -> 2.53 | G18: =IFERROR((E18+F18)/2," ") -> 2.565 | H18: =ROUNDUP(RAND()/J18/3,2) -> 0.14 | I18: =ROUNDUP(RAND()/K18/3,2) -> 0.1 | J18: =J17 -> 1.5 | K18: =K17 -> 1.5
A19: 15 | C19: 525 | D19: =G19-G$4 -> 3.08 | E19: =ROUNDUP(E18+H19,3) -> 3.372 | F19: =ROUNDUP(F18+I19,3) -> 2.788 | G19: =IFERROR((E19+F19)/2," ") -> 3.08 | H19: =ROUNDUP(RAND()/J19,2)/J$4 -> 0.77142857 | I19: =ROUNDUP(RAND()/K19,2)/K$4 -> 0.25714286 | J19: =J18 -> 1.5 | K19: =K18 -> 1.5
A20: 16 | C20: 560 | D20: =G20-G$4 -> 3.6945 | E20: =ROUNDUP(E19+H20,3) -> 4.272 | F20: =ROUNDUP(F19+I20,3) -> 3.117 | G20: =IFERROR((E20+F20)/2," ") -> 3.6945 | H20: =ROUNDUP(RAND()/J20,2)/J$4 -> 0.9 | I20: =ROUNDUP(RAND()/K20,2)/K$4 -> 0.32857143 | J20: =J19 -> 1.5 | K20: =K19 -> 1.5
H21: =ROUNDUP(RAND()/J21,2)/J$4 -> 0.28571429 | I21: =ROUNDUP(RAND()/K21,2)/K$4 -> #DIV/0! | J21: =J20 -> 1.5
H22: =ROUNDUP(RAND()/J22,2)/J$4 -> 0.74285714 | I22: =ROUNDUP(RAND()/K22,2)/K$4 -> #DIV/0! | J22: =J21 -> 1.5 | K22: =K21 -> 0
H23: =ROUNDUP(RAND()/J23,2)/J$4 -> 0.18571429 | I23: =ROUNDUP(RAND()/K23,2)/K$4 -> #DIV/0! | J23: =J22 -> 1.5 | K23: =K22 -> 0
H24: =ROUNDUP(RAND()/J24,2)/J$4 -> 0.71428571 | I24: =ROUNDUP(RAND()/K24,2)/K$4 -> #DIV/0! | J24: =J23 -> 1.5 | K24: =K23 -> 0

Sheet AUTO
E1: 선택하여 붙여 넣기 값
A2: 재 하 하 중 | E2: 변위량
A3: 시험 단계 | B3: 하 중 (kgf) | C3: 하중강도 (kN/㎡) | D3: 누계침하량 (mm) | E3: 좌 | F3: 우 | G3: 평균 (mm)
A4: 0 | B4: 0 | C4: 0 | D4: 0 | E4: 0 | F4: 0 | G4: =(E4+F4)/2 -> 0 | I4: 계수 | J4: 1.2 | K4: 1.2
A5: 1 | B5: 450 | C5: 35 | D5: =G5-G$4 -> 0.04 | E5: =ROUNDUP(E4+H5,3) -> 0.02 | F5: =ROUNDUP(F4+I5,3) -> 0.06 | G5: =IFERROR((E5+F5)/2," ") -> 0.04 | H5: =ROUNDUP(RAND()/J5/3,2) -> 0.02 | I5: =ROUNDUP(RAND()/K5/3,2) -> 0.06 | J5: =J4 -> 1.2 | K5: =K4 -> 1.2
A6: 2 | B6: 900 | C6: 70 | D6: =G6-G$4 -> 0.175 | E6: =ROUNDUP(E5+H6,3) -> 0.04 | F6: =ROUNDUP(F5+I6,3) -> 0.31 | G6: =IFERROR((E6+F6)/2," ") -> 0.175 | H6: =ROUNDUP(RAND()/J6/3,2) -> 0.02 | I6: =ROUNDUP(RAND()/K6/3,2) -> 0.25 | J6: =J5 -> 1.2 | K6: =K5 -> 1.2
A7: 3 | B7: 1350 | C7: 105 | D7: =G7-G$4 -> 0.29 | E7: =ROUNDUP(E6+H7,3) -> 0.22 | F7: =ROUNDUP(F6+I7,3) -> 0.36 | G7: =IFERROR((E7+F7)/2," ") -> 0.29 | H7: =ROUNDUP(RAND()/J7/3,2) -> 0.18 | I7: =ROUNDUP(RAND()/K7/3,2) -> 0.05 | J7: =J6 -> 1.2 | K7: =K6 -> 1.2
A8: 4 | B8: 1800 | C8: 140 | D8: =G8-G$4 -> 0.47 | E8: =ROUNDUP(E7+H8,3) -> 0.33 | F8: =ROUNDUP(F7+I8,3) -> 0.61 | G8: =IFERROR((E8+F8)/2," ") -> 0.47 | H8: =ROUNDUP(RAND()/J8/3,2) -> 0.11 | I8: =ROUNDUP(RAND()/K8/3,2) -> 0.25 | J8: =J7 -> 1.2 | K8: =K7 -> 1.2
A9: 5 | B9: 2250 | C9: 175 | D9: =G9-G$4 -> 0.545 | E9: =ROUNDUP(E8+H9,3) -> 0.47 | F9: =ROUNDUP(F8+I9,3) -> 0.62 | G9: =IFERROR((E9+F9)/2," ") -> 0.545 | H9: =ROUNDUP(RAND()/J9/3,2) -> 0.14 | I9: =ROUNDUP(RAND()/K9/3,2) -> 0.01 | J9: =J8 -> 1.2 | K9: =K8 -> 1.2
A10: 6 | B10: 2700 | C10: 210 | D10: =G10-G$4 -> 0.7 | E10: =ROUNDUP(E9+H10,3) -> 0.66 | F10: =ROUNDUP(F9+I10,3) -> 0.74 | G10: =IFERROR((E10+F10)/2," ") -> 0.7 | H10: =ROUNDUP(RAND()/J10/3,2) -> 0.19 | I10: =ROUNDUP(RAND()/K10/3,2) -> 0.12 | J10: =J9 -> 1.2 | K10: =K9 -> 1.2
A11: 7 | B11: 3140 | C11: 245 | D11: =G11-G$4 -> 0.9 | E11: =ROUNDUP(E10+H11,3) -> 0.9 | F11: =ROUNDUP(F10+I11,3) -> 0.9 | G11: =IFERROR((E11+F11)/2," ") -> 0.9 | H11: =ROUNDUP(RAND()/J11/3,2) -> 0.24 | I11: =ROUNDUP(RAND()/K11/3,2) -> 0.16 | J11: =J10 -> 1.2 | K11: =K10 -> 1.2
A12: 8 | B12: 3590 | C12: 280 | D12: =G12-G$4 -> 1.01 | E12: =ROUNDUP(E11+H12,3) -> 1.02 | F12: =ROUNDUP(F11+I12,3) -> 1 | G12: =IFERROR((E12+F12)/2," ") -> 1.01 | H12: =ROUNDUP(RAND()/J12/3,2) -> 0.12 | I12: =ROUNDUP(RAND()/K12/3,2) -> 0.1 | J12: =J11 -> 1.2 | K12: =K11 -> 1.2
A13: 9 | B13: 4040 | C13: 315 | D13: =G13-G$4 -> 1.035 | E13: =ROUNDUP(E12+H13,3) -> 1.06 | F13: =ROUNDUP(F12+I13,3) -> 1.01 | G13: =IFERROR((E13+F13)/2," ") -> 1.035 | H13: =ROUNDUP(RAND()/J13/3,2) -> 0.04 | I13: =ROUNDUP(RAND()/K13/3,2) -> 0.01 | J13: =J12 -> 1.2 | K13: =K12 -> 1.2
A14: 10 | B14: 4490 | C14: 350 | D14: =G14-G$4 -> 1.105 | E14: =ROUNDUP(E13+H14,3) -> 1.14 | F14: =ROUNDUP(F13+I14,3) -> 1.07 | G14: =IFERROR((E14+F14)/2," ") -> 1.105 | H14: =ROUNDUP(RAND()/J14/3,2) -> 0.08 | I14: =ROUNDUP(RAND()/K14/3,2) -> 0.06 | J14: =J13 -> 1.2 | K14: =K13 -> 1.2
A15: 11 | B15: 4940 | C15: 385 | D15: =G15-G$4 -> 1.245 | E15: =ROUNDUP(E14+H15,3) -> 1.19 | F15: =ROUNDUP(F14+I15,3) -> 1.3 | G15: =IFERROR((E15+F15)/2," ") -> 1.245 | H15: =ROUNDUP(RAND()/J15/3,2) -> 0.05 | I15: =ROUNDUP(RAND()/K15/3,2) -> 0.23 | J15: =J14 -> 1.2 | K15: =K14 -> 1.2
A16: 12 | B16: 5390 | C16: 420 | D16: =G16-G$4 -> 1.345 | E16: =ROUNDUP(E15+H16,3) -> 1.24 | F16: =ROUNDUP(F15+I16,3) -> 1.45 | G16: =IFERROR((E16+F16)/2," ") -> 1.345 | H16: =ROUNDUP(RAND()/J16/3,2) -> 0.05 | I16: =ROUNDUP(RAND()/K16/3,2) -> 0.15 | J16: =J15 -> 1.2 | K16: =K15 -> 1.2
A17: 13 | C17: 455 | D17: =G17-G$4 -> 1.495 | E17: =ROUNDUP(E16+H17,3) -> 1.38 | F17: =ROUNDUP(F16+I17,3) -> 1.61 | G17: =IFERROR((E17+F17)/2," ") -> 1.495 | H17: =ROUNDUP(RAND()/J17/3,2) -> 0.14 | I17: =ROUNDUP(RAND()/K17/3,2) -> 0.16 | J17: =J16 -> 1.2 | K17: =K16 -> 1.2
A18: 14 | C18: 490 | D18: =G18-G$4 -> 1.66 | E18: =ROUNDUP(E17+H18,3) -> 1.46 | F18: =ROUNDUP(F17+I18,3) -> 1.86 | G18: =IFERROR((E18+F18)/2," ") -> 1.66 | H18: =ROUNDUP(RAND()/J18/3,2) -> 0.08 | I18: =ROUNDUP(RAND()/K18/3,2) -> 0.25 | J18: =J17 -> 1.2 | K18: =K17 -> 1.2
A19: 15 | C19: 525 | D19: =G19-G$4 -> 2.181 | E19: =ROUNDUP(E18+H19,3) -> 1.902 | F19: =ROUNDUP(F18+I19,3) -> 2.46 | G19: =IFERROR((E19+F19)/2," ") -> 2.181 | H19: =ROUNDUP(RAND()/J19,2)/J$4 -> 0.44166667 | I19: =ROUNDUP(RAND()/K19,2)/K$4 -> 0.6 | J19: =J18 -> 1.2 | K19: =K18 -> 1.2
A20: 16 | C20: 560 | D20: =G20-G$4 -> 2.444 | E20: =ROUNDUP(E19+H20,3) -> 1.936 | F20: =ROUNDUP(F19+I20,3) -> 2.952 | G20: =IFERROR((E20+F20)/2," ") -> 2.444 | H20: =ROUNDUP(RAND()/J20,2)/J$4 -> 0.033333333 | I20: =ROUNDUP(RAND()/K20,2)/K$4 -> 0.49166667 | J20: =J19 -> 1.2 | K20: =K19 -> 1.2
H21: =ROUNDUP(RAND()/J21,2)/J$4 -> 0.53333333 | I21: =ROUNDUP(RAND()/K21,2)/K$4 -> 0.4 | J21: =J20 -> 1.2 | K21: =K20 -> 1.2
H22: =ROUNDUP(RAND()/J22,2)/J$4 -> 0.033333333 | I22: =ROUNDUP(RAND()/K22,2)/K$4 -> 0.55833333 | J22: =J21 -> 1.2 | K22: =K21 -> 1.2
H23: =ROUNDUP(RAND()/J23,2)/J$4 -> 0.083333333 | I23: =ROUNDUP(RAND()/K23,2)/K$4 -> 0.53333333 | J23: =J22 -> 1.2 | K23: =K22 -> 1.2
H24: =ROUNDUP(RAND()/J24,2)/J$4 -> 0.11666667 | I24: =ROUNDUP(RAND()/K24,2)/K$4 -> 0.016666667 | J24: =J23 -> 1.2 | K24: =K23 -> 1.2

Sheet List
A1: 시험번호, 시험일자, 위치 -> List에서 변경하면 시험 시트 자동 변경 시험결과 -> 시험 시트에서 변경하면 Rist에서 자동변경 | H1: AUTO 선택하여 붙여넣기 -> 값
A2: 붉은색 -> data 입력 | H2: Data | J2: 1 | L2: 2 | N2: 3 | P2: 4 | R2: 5 | T2: 6 | V2: 7 | X2: 8 | Z2: 9 | AB2: 10 | AD2: 11 | AF2: 12 | AH2: 13 | AJ2: 14 | AL2: 15 | AN2: 16 | AP2: 17 | AR2: 18 | AT2: 19 | AV2: 20
A3: 시험번호 | B3: 시험일자 | C3: 위 치 | D3: 시험 결과 | E3: 기 준 | F3: 합부판정 | H3: 시험단계 | I3: 하중강도 | J3: 좌(mm) | K3: 우(mm) | L3: 좌(mm) | M3: 우(mm) | N3: 좌(mm) | O3: 우(mm) | P3: 좌(mm) | Q3: 우(mm) | R3: 좌(mm) | S3: 우(mm) | T3: 좌(mm) | U3: 우(mm) | V3: 좌(mm) | W3: 우(mm) | X3: 좌(mm) | Y3: 우(mm) | Z3: 좌(mm) | AA3: 우(mm) | AB3: 좌(mm) | AC3: 우(mm) | AD3: 좌(mm) | AE3: 우(mm) | AF3: 좌(mm) | AG3: 우(mm) | AH3: 좌(mm) | AI3: 우(mm) | AJ3: 좌(mm) | AK3: 우(mm) | AL3: 좌(mm) | AM3: 우(mm) | AN3: 좌(mm) | AO3: 우(mm) | AP3: 좌(mm) | AQ3: 우(mm) | AR3: 좌(mm) | AS3: 우(mm) | AT3: 좌(mm) | AU3: 우(mm) | AV3: 좌(mm) | AW3: 우(mm)
A4: 1 | B4: 46160 | C4: 중로(집) 3-14 (No.6 ~ No.9),소로(국)3-17 노체 1단(3층) | D4: ='1'!K14 -> 197.2 | E4: 147 | F4: =IF(D4>E4,"합격","불합격") -> 합격 | H4: 0 | I4: 0 | J4: 0 | K4: 0 | L4: 0 | M4: 0 | N4: 0 | O4: 0 | P4: 0 | Q4: 0 | R4: 0 | S4: 0 | T4: 0 | U4: 0 | V4: 0 | W4: 0 | X4: 0 | Y4: 0 | Z4: 0 | AA4: 0 | AB4: 0 | AC4: 0 | AD4: 0 | AE4: 0 | AF4: 0 | AG4: 0 | AH4: 0 | AI4: 0 | AJ4: 0 | AK4: 0 | AL4: 0 | AM4: 0 | AN4: 0 | AO4: 0 | AP4: 0 | AQ4: 0 | AR4: 0 | AS4: 0 | AT4: 0 | AU4: 0 | AV4: 0 | AW4: 0
A5: =A4+1 -> 2 | B5: 46160 | C5: 중로(집) 3-14 (No.6 ~ No.9),소로(국)3-17 노체 2단(6층) | D5: ='2'!K14 -> 199.6 | E5: 147 | F5: =IF(D5>E5,"합격","불합격") -> 합격 | H5: 1 | I5: 35 | J5: 0.22 | K5: 0.34 | L5: 0.19 | M5: 0.09 | N5: 0.22 | O5: 0.05 | P5: 0.37 | Q5: 0.23 | R5: 0.04 | S5: 0.12 | T5: 0.14 | U5: 0.02 | V5: 0.21 | W5: 0.26 | X5: 0.27 | Y5: 0.24 | Z5: 0.26 | AA5: 0.12 | AB5: 0.01 | AC5: 0.14 | AD5: 0.23 | AE5: 0.29 | AF5: 0.15 | AG5: 0.17 | AH5: 0.15 | AI5: 0.04 | AJ5: 0.01 | AK5: 0.25 | AL5: 0.33 | AM5: 0.12 | AN5: 0.02 | AO5: 0.26 | AP5: 0.13 | AQ5: 0.07 | AR5: 0.35 | AS5: 0.04 | AT5: 0.35 | AU5: 0.3 | AV5: 0.37 | AW5: 0.08
A6: =A5+1 -> 3 | B6: 46160 | C6: 중로(집) 3-16 (No.36 ~ No.41) 노체 1단(3층) | D6: ='3'!K14 -> 195.2 | E6: 147 | F6: =IF(D6>E6,"합격","불합격") -> 합격 | H6: 2 | I6: 70 | J6: 0.43 | K6: 0.36 | L6: 0.54 | M6: 0.46 | N6: 0.43 | O6: 0.15 | P6: 0.74 | Q6: 0.58 | R6: 0.37 | S6: 0.23 | T6: 0.2 | U6: 0.36 | V6: 0.29 | W6: 0.54 | X6: 0.57 | Y6: 0.4 | Z6: 0.37 | AA6: 0.34 | AB6: 0.23 | AC6: 0.31 | AD6: 0.37 | AE6: 0.39 | AF6: 0.41 | AG6: 0.44 | AH6: 0.4 | AI6: 0.34 | AJ6: 0.09 | AK6: 0.39 | AL6: 0.57 | AM6: 0.47 | AN6: 0.29 | AO6: 0.4 | AP6: 0.49 | AQ6: 0.09 | AR6: 0.41 | AS6: 0.09 | AT6: 0.38 | AU6: 0.55 | AV6: 0.45 | AW6: 0.4
A7: =A6+1 -> 4 | B7: 46160 | C7: 중로(집) 3-16 (No.36 ~ No.41) 노체 2단(6층) | D7: ='4'!K14 -> 188.8 | E7: 147 | F7: =IF(D7>E7,"합격","불합격") -> 합격 | H7: 3 | I7: 105 | J7: 0.55 | K7: 0.43 | L7: 0.85 | M7: 0.66 | N7: 0.52 | O7: 0.38 | P7: 0.89 | Q7: 0.63 | R7: 0.4 | S7: 0.46 | T7: 0.32 | U7: 0.44 | V7: 0.45 | W7: 0.65 | X7: 0.77 | Y7: 0.46 | Z7: 0.69 | AA7: 0.53 | AB7: 0.37 | AC7: 0.59 | AD7: 0.69 | AE7: 0.5 | AF7: 0.62 | AG7: 0.69 | AH7: 0.75 | AI7: 0.59 | AJ7: 0.36 | AK7: 0.5 | AL7: 0.63 | AM7: 0.72 | AN7: 0.44 | AO7: 0.5 | AP7: 0.5 | AQ7: 0.3 | AR7: 0.43 | AS7: 0.35 | AT7: 0.75 | AU7: 0.68 | AV7: 0.81 | AW7: 0.56
A8: =A7+1 -> 5 | B8: 46161 | C8: 중로(집) 3-14 (No.6 ~ No.9),소로(국)3-17 노체 3단(9층) | D8: ='5'!K14 -> 182.8 | E8: 147 | F8: =IF(D8>E8,"합격","불합격") -> 합격 | H8: 4 | I8: 140 | J8: 0.92 | K8: 0.74 | L8: 0.87 | M8: 1.03 | N8: 0.54 | O8: 0.55 | P8: 0.95 | Q8: 0.68 | R8: 0.55 | S8: 0.48 | T8: 0.33 | U8: 0.81 | V8: 0.82 | W8: 0.88 | X8: 1.04 | Y8: 0.83 | Z8: 0.89 | AA8: 0.66 | AB8: 0.42 | AC8: 0.86 | AD8: 0.99 | AE8: 0.73 | AF8: 0.69 | AG8: 0.71 | AH8: 1.05 | AI8: 0.75 | AJ8: 0.67 | AK8: 0.87 | AL8: 0.95 | AM8: 0.78 | AN8: 0.72 | AO8: 0.62 | AP8: 0.75 | AQ8: 0.4 | AR8: 0.68 | AS8: 0.39 | AT8: 0.87 | AU8: 0.72 | AV8: 1.15 | AW8: 0.83
A9: =A8+1 -> 6 | B9: 46161 | C9: 중로(집) 3-14 (No.6 ~ No.9),소로(국)3-17 노체 4단(12층) | D9: ='6'!K14 -> 177.2 | E9: 147 | F9: =IF(D9>E9,"합격","불합격") -> 합격 | H9: 5 | I9: 175 | J9: 0.98 | K9: 1.03 | L9: 1 | M9: 1.22 | N9: 0.59 | O9: 0.69 | P9: 1.21 | Q9: 0.75 | R9: 0.78 | S9: 0.5 | T9: 0.57 | U9: 1.03 | V9: 1.18 | W9: 1.2 | X9: 1.38 | Y9: 0.93 | Z9: 1.14 | AA9: 0.81 | AB9: 0.51 | AC9: 0.96 | AD9: 1.2 | AE9: 0.98 | AF9: 1.05 | AG9: 0.79 | AH9: 1.19 | AI9: 0.91 | AJ9: 0.94 | AK9: 1.23 | AL9: 1.32 | AM9: 0.97 | AN9: 0.8 | AO9: 0.76 | AP9: 0.97 | AQ9: 0.45 | AR9: 0.94 | AS9: 0.49 | AT9: 1.2 | AU9: 0.83 | AV9: 1.34 | AW9: 0.88
A10: =A9+1 -> 7 | B10: 46161 | C10: 중로(집) 3-16 (No.36 ~ No.41) 노체 3단(9층) | D10: ='7'!K14 -> 187.6 | E10: 147 | F10: =IF(D10>E10,"합격","불합격") -> 합격 | H10: 6 | I10: 210 | J10: 1.11 | K10: 1.22 | L10: 1.07 | M10: 1.53 | N10: 0.92 | O10: 0.76 | P10: 1.28 | Q10: 1.12 | R10: 0.79 | S10: 0.65 | T10: 0.69 | U10: 1.35 | V10: 1.36 | W10: 1.41 | X10: 1.53 | Y10: 1.28 | Z10: 1.4 | AA10: 0.97 | AB10: 0.54 | AC10: 1.12 | AD10: 1.26 | AE10: 1.09 | AF10: 1.16 | AG10: 0.84 | AH10: 1.46 | AI10: 0.95 | AJ10: 1.23 | AK10: 1.44 | AL10: 1.61 | AM10: 1.35 | AN10: 0.99 | AO10: 0.99 | AP10: 1.25 | AQ10: 0.65 | AR10: 1.07 | AS10: 0.63 | AT10: 1.34 | AU10: 1.16 | AV10: 1.71 | AW10: 1.23
A11: =A10+1 -> 8 | B11: 46161 | C11: 중로(집) 3-16 (No.36 ~ No.41) 노체 4단(12층) | D11: ='8'!K14 -> 176 | E11: 147 | F11: =IF(D11>E11,"합격","불합격") -> 합격 | H11: 7 | I11: 245 | J11: 1.32 | K11: 1.34 | L11: 1.18 | M11: 1.58 | N11: 0.97 | O11: 1.07 | P11: 1.33 | Q11: 1.28 | R11: 1.15 | S11: 0.93 | T11: 0.98 | U11: 1.65 | V11: 1.53 | W11: 1.56 | X11: 1.73 | Y11: 1.63 | Z11: 1.52 | AA11: 1.2 | AB11: 0.78 | AC11: 1.41 | AD11: 1.29 | AE11: 1.36 | AF11: 1.44 | AG11: 1.2 | AH11: 1.72 | AI11: 1.02 | AJ11: 1.5 | AK11: 1.61 | AL11: 1.68 | AM11: 1.41 | AN11: 1.35 | AO11: 1.3 | AP11: 1.4 | AQ11: 0.87 | AR11: 1.43 | AS11: 0.66 | AT11: 1.69 | AU11: 1.31 | AV11: 2.05 | AW11: 1.6
A12: =A11+1 -> 9 | B12: 46164 | C12: 중로(집) 3-14 (No.6 ~ No.9),소로(국)3-17 노체 5단(15층) | D12: ='9'!K14 -> 170 | E12: 147 | F12: =IF(D12>E12,"합격","불합격") -> 합격 | H12: 8 | I12: 280 | J12: 1.39 | K12: 1.64 | L12: 1.36 | M12: 1.87 | N12: 1.28 | O12: 1.27 | P12: 1.61 | Q12: 1.44 | R12: 1.36 | S12: 1.3 | T12: 1.13 | U12: 1.77 | V12: 1.84 | W12: 1.67 | X12: 1.77 | Y12: 1.65 | Z12: 1.68 | AA12: 1.42 | AB12: 0.83 | AC12: 1.61 | AD12: 1.49 | AE12: 1.37 | AF12: 1.69 | AG12: 1.41 | AH12: 1.97 | AI12: 1.21 | AJ12: 1.67 | AK12: 1.69 | AL12: 1.9 | AM12: 1.68 | AN12: 1.36 | AO12: 1.63 | AP12: 1.77 | AQ12: 1 | AR12: 1.75 | AS12: 1.01 | AT12: 1.84 | AU12: 1.39 | AV12: 2.41 | AW12: 1.73
A13: =A12+1 -> 10 | B13: 46164 | C13: 중로(집) 3-14 (No.6 ~ No.9),소로(국)3-17 노체 6단(18층) | D13: ='10'!K14 -> 166 | E13: 147 | F13: =IF(D13>E13,"합격","불합격") -> 합격 | H13: 9 | I13: 315 | J13: 1.48 | K13: 1.69 | L13: 1.55 | M13: 2 | N13: 1.39 | O13: 1.31 | P13: 1.84 | Q13: 1.64 | R13: 1.47 | S13: 1.4 | T13: 1.28 | U13: 1.92 | V13: 2.21 | W13: 1.96 | X13: 1.8 | Y13: 1.92 | Z13: 1.69 | AA13: 1.71 | AB13: 0.85 | AC13: 1.81 | AD13: 1.72 | AE13: 1.58 | AF13: 1.88 | AG13: 1.42 | AH13: 2.02 | AI13: 1.45 | AJ13: 1.97 | AK13: 1.79 | AL13: 2.05 | AM13: 1.75 | AN13: 1.5 | AO13: 1.77 | AP13: 1.93 | AQ13: 1.35 | AR13: 2.09 | AS13: 1.09 | AT13: 2.2 | AU13: 1.49 | AV13: 2.71 | AW13: 1.96
A14: =A13+1 -> 11 | B14: 46164 | C14: 중로(집) 3-16 (No.36 ~ No.41) 노체 5단(15층) | D14: ='11'!K14 -> 163.2 | E14: 147 | F14: =IF(D14>E14,"합격","불합격") -> 합격 | H14: 10 | I14: 350 | L14: 1.67 | M14: 2.35 | N14: 1.45 | O14: 1.67 | P14: 1.99 | Q14: 1.9 | R14: 1.58 | S14: 1.71 | T14: 1.56 | U14: 2.15 | V14: 2.45 | W14: 2.03 | X14: 1.9 | Y14: 2.29 | Z14: 1.86 | AA14: 1.93 | AB14: 1.16 | AC14: 2.12 | AD14: 1.99 | AE14: 1.92 | AF14: 1.94 | AG14: 1.75 | AH14: 2.25 | AI14: 1.53 | AJ14: 1.98 | AK14: 1.85 | AL14: 2.39 | AM14: 1.92 | AN14: 1.82 | AO14: 2.03 | AP14: 2.11 | AQ14: 1.36 | AR14: 2.26 | AS14: 1.33 | AT14: 2.44 | AU14: 1.59 | AV14: 2.99 | AW14: 2.22
A15: =A14+1 -> 12 | B15: 46164 | C15: 중로(집) 3-16 (No.36 ~ No.41) 노체 6단(18층) | D15: ='12'!K14 -> 166.4 | E15: 147 | F15: =IF(D15>E15,"합격","불합격") -> 합격 | H15: 11 | I15: 385 | L15: 1.74 | M15: 2.68 | N15: 1.46 | O15: 1.91 | P15: 2.14 | Q15: 1.95 | R15: 1.62 | S15: 1.88 | T15: 1.85 | U15: 2.46 | V15: 2.69 | W15: 2.37 | X15: 1.95 | Y15: 2.55 | Z15: 2.16 | AA15: 2.21 | AB15: 1.3 | AC15: 2.33 | AD15: 2.2 | AE15: 2.1 | AF15: 2.06 | AG15: 1.82 | AH15: 2.26 | AI15: 1.84 | AJ15: 2.17 | AK15: 2.07 | AL15: 2.58 | AM15: 2.29 | AN15: 2.03 | AO15: 2.19 | AP15: 2.16 | AQ15: 1.39 | AR15: 2.47 | AS15: 1.34 | AT15: 2.77 | AU15: 1.83 | AV15: 3.24 | AW15: 2.31
A16: =A15+1 -> 13 | B16: 46168 | C16: 중로(집) 3-14 (No.6 ~ No.9),소로(국)3-17 노체 7단(21층) | D16: ='13'!K14 -> 162.8 | E16: 147 | F16: =IF(D16>E16,"합격","불합격") -> 합격 | H16: 12 | I16: 420 | L16: 1.98 | M16: 2.97 | N16: 1.63 | O16: 2.04 | P16: 2.3 | Q16: 2.03 | R16: 1.92 | S16: 1.91 | T16: 1.86 | U16: 2.83 | V16: 2.83 | W16: 2.73 | X16: 1.97 | Y16: 2.62 | Z16: 2.25 | AA16: 2.49 | AB16: 1.42 | AC16: 2.42 | AD16: 2.31 | AE16: 2.19 | AF16: 2.24 | AG16: 2.16 | AH16: 2.59 | AI16: 1.93 | AJ16: 2.26 | AK16: 2.23 | AL16: 2.82 | AM16: 2.5 | AN16: 2.34 | AO16: 2.23 | AP16: 2.52 | AQ16: 1.72 | AR16: 2.51 | AS16: 1.48 | AT16: 2.97 | AU16: 2 | AV16: 3.5 | AW16: 2.34
A17: =A16+1 -> 14 | B17: 46168 | C17: 중로(집) 3-14 (No.6 ~ No.9),소로(국)3-17 노체 8단(24층) | D17: ='14'!K14 -> 166 | E17: 147 | F17: =IF(D17>E17,"합격","불합격") -> 합격
A18: =A17+1 -> 15 | B18: 46168 | C18: 중로(집) 3-16 (No.36 ~ No.41) 노체 7단(21층) | D18: ='15'!K14 -> 171.6 | E18: 147 | F18: =IF(D18>E18,"합격","불합격") -> 합격
A19: =A18+1 -> 16 | B19: 46168 | C19: 중로(집) 3-16 (No.36 ~ No.41) 노체 8단(24층) | D19: ='16'!K14 -> 167.6 | E19: 147 | F19: =IF(D19>E19,"합격","불합격") -> 합격
A20: =A19+1 -> 17 | B20: 46169 | C20: 중로(집) 3-14 (No.6 ~ No.9),소로(국)3-17 노체 9단(27층) | D20: ='17'!K14 -> 170.8 | E20: 147 | F20: =IF(D20>E20,"합격","불합격") -> 합격 | H20: 12 | I20: 420 | L20: 1.98 | M20: 2.97 | N20: 1.63 | O20: 2.04 | P20: 2.3 | Q20: 2.03 | R20: 1.92 | S20: 1.91 | T20: 1.86 | U20: 2.83 | V20: 2.83 | W20: 2.73 | X20: 1.97 | Y20: 2.62 | Z20: 2.25 | AA20: 2.49 | AB20: 1.42 | AC20: 2.42 | AD20: 2.31 | AE20: 2.19 | AF20: 2.24 | AG20: 2.16 | AH20: 2.59 | AI20: 1.93 | AJ20: 2.26 | AK20: 2.23 | AL20: 2.82 | AM20: 2.5 | AN20: 2.34 | AO20: 2.23 | AP20: 2.52 | AQ20: 1.72 | AR20: 2.51 | AS20: 1.48 | AT20: 2.97 | AU20: 2 | AV20: 3.5 | AW20: 2.34
A21: =A20+1 -> 18 | B21: 46169 | C21: 중로(집) 3-14 (No.6 ~ No.9),소로(국)3-17 노체 10단(30층) | D21: ='18'!K14 -> 169.6 | E21: 147 | F21: =IF(D21>E21,"합격","불합격") -> 합격
A22: =A21+1 -> 19 | B22: 46169 | C22: 중로(집) 3-16 (No.36 ~ No.41) 노체 9단(27층) | D22: ='19'!K14 -> 165.2 | E22: 147 | F22: =IF(D22>E22,"합격","불합격") -> 합격
A23: =A22+1 -> 20 | B23: 46169 | C23: 중로(집) 3-16 (No.36 ~ No.41) 노체 10단(30층) | D23: ='20'!K14 -> 162.4 | E23: 147 | F23: =IF(D23>E23,"합격","불합격") -> 합격
A24: =A23+1 -> 21 | B24: 46170 | C24: 중로(집) 3-12 (No.17 ~ No.20) 노체 1단(3층) | D24: ='21'!K14 -> 173.2 | E24: 147 | F24: =IF(D24>E24,"합격","불합격") -> 합격
A25: =A24+1 -> 22 | B25: 46170 | C25: 중로(집) 3-12 (No.17 ~ No.20) 노체 2단(6층) | D25: ='22'!K14 -> 168 | E25: 147 | F25: =IF(D25>E25,"합격","불합격") -> 합격
A26: =A25+1 -> 23 | B26: 46170 | C26: 중로(집) 3-16 (No.36 ~ No.41) 노체 11단(33층) | D26: ='23'!K14 -> 181.2 | E26: 147 | F26: =IF(D26>E26,"합격","불합격") -> 합격
A27: =A26+1 -> 24 | B27: 46170 | C27: 중로(집) 3-16 (No.36 ~ No.41) 노체 12단(36층) | D27: ='24'!K14 -> 183.2 | E27: 147 | F27: =IF(D27>E27,"합격","불합격") -> 합격
A28: =A27+1 -> 25 | B28: 46171 | C28: 중로(집) 3-12 (No.17 ~ No.20) 노체 3단(9층) | D28: ='25'!K14 -> 172.4 | E28: 147 | F28: =IF(D28>E28,"합격","불합격") -> 합격
A29: =A28+1 -> 26 | B29: 46171 | C29: 중로(집) 3-12 (No.17 ~ No.20) 노체 4단(12층) | D29: ='26'!K14 -> 171.2 | E29: 147 | F29: =IF(D29>E29,"합격","불합격") -> 합격
A30: =A29+1 -> 27 | B30: 46171 | C30: 중로(집) 3-16 (No.36 ~ No.41) 노체 13단(39층) | D30: ='27'!K14 -> 182.4 | E30: 147 | F30: =IF(D30>E30,"합격","불합격") -> 합격
A31: =A30+1 -> 28 | B31: 46174 | C31: 중로(집) 3-12 (No.17 ~ No.20) 노체 5단(15층) | D31: ='28'!K14 -> 198.4 | E31: 147 | F31: =IF(D31>E31,"합격","불합격") -> 합격
A32: =A31+1 -> 29 | B32: 46174 | C32: 중로(집) 3-12 (No.17 ~ No.20) 노체 6단(18층) | D32: ='29'!K14 -> 203.2 | E32: 147 | F32: =IF(D32>E32,"합격","불합격") -> 합격
A33: =A32+1 -> 30 | B33: 46174 | C33: 중로(집) 3-16 (No.36 ~ No.41) 노체 14단(42층) | D33: ='30'!K14 -> 200.4 | E33: 147 | F33: =IF(D33>E33,"합격","불합격") -> 합격
A34: =A33+1 -> 31 | B34: 46175 | C34: 중로(집) 3-12 (No.17 ~ No.20) 노체 7단(21층) | D34: ='31'!K14 -> 199.6 | E34: 147 | F34: =IF(D34>E34,"합격","불합격") -> 합격
A35: =A34+1 -> 32 | B35: 46175 | C35: 중로(집) 3-12 (No.17 ~ No.20) 노체 8단(24층) | D35: ='32'!K14 -> 200.8 | E35: 147 | F35: =IF(D35>E35,"합격","불합격") -> 합격
A36: =A35+1 -> 33 | B36: 46177 | C36: 중로(집) 3-16 (No.36 ~ No.50) 노체 15단(45층) - 1회 | D36: ='33'!K14 -> 212 | E36: 147 | F36: =IF(D36>E36,"합격","불합격") -> 합격
A37: =A36+1 -> 34 | B37: 46177 | C37: 중로(집) 3-16 (No.36 ~ No.50) 노체 15단(45층) - 2회 | D37: ='34'!K14 -> 209.6 | E37: 147 | F37: =IF(D37>E37,"합격","불합격") -> 합격
A38: =A37+1 -> 35 | B38: 46177 | C38: 중로(집) 3-12 (No.17 ~ No.20) 노체 9단(27층) | D38: ='35'!K14 -> 209.2 | E38: 147 | F38: =IF(D38>E38,"합격","불합격") -> 합격
A39: =A38+1 -> 36 | B39: 46177 | C39: 중로(집) 3-12 (No.17 ~ No.20) 노체 10단(30층) | D39: ='36'!K14 -> 214 | E39: 147 | F39: =IF(D39>E39,"합격","불합격") -> 합격
A40: =A39+1 -> 37 | B40: 46178 | C40: 중로(집) 3-12 (No.17 ~ No.20) 노체 11단(33층) | D40: ='37'!K14 -> 205.2 | E40: 147 | F40: =IF(D40>E40,"합격","불합격") -> 합격
...

Sheet 49
A1: 평 판 재 하 시 험 | L1: K30=2.2×K75 K30=1.3×K40
A2: 공 사 명 : | B2: 진천메가폴리스 산업단지 조성사업 | F2: 시험일자 : | G2: =List!B52 -> 46217 | K2: 시험번호
A3: 시험번호 : | B3: =List!A52 -> 49 | F3: 위 치 : | G3: =List!C52 -> 중로(집) 3-16 (No.36 ~ No.50, 우측) 노체 21단(63층) | K3: 1 | L3: 지반반력계수 환산
A4: 재하조건 | B4: 재하판 지름 : | C4: 300 | D4: 평판면적 : | E4: =30*30/4*3.14 -> 706.5 | F4: 초기하중 : | G4: 35kN/㎡ | H4: KS F 2310
A5: 시간 min - s | B5: 하중 | D5: 변위계의 눈금(mm) | G5: 침하량 (mm) | H5: 적 용 시 방 기 준 (콘크리트포장)
B6: 전하중 (kN) | C6: 재하응력 (kN/㎡) | D6: 왼쪽 | E6: 오른쪽 | F6: 평균
A7: 0 | B7: 0 | C7: 0 | D7: 0 | E7: 0 | F7: =(D7+E7)/2 -> 0 | G7: 0 | H7: K30=147 MN/㎥ 이상 | J7: 노체
A8: =TIME(,RAND()*1+(1-0),RAND()*10+4) -> 0.00074074074 | B8: =C8*0.07065 -> 2.47275 | C8: 35 | D8: 0.12 | E8: 0.13 | F8: =IFERROR((D8+E8)/2," ") -> 0.125 | G8: =F8-F7 -> 0.125 | P8: 0.1 | Q8: 0.1 | S8: =E8+P8 -> 0.23 | T8: =F8+Q8 -> 0.225
A9: =A8+TIME(,RAND()*1+(1-0),RAND()*10+10) -> 0.0015625 | B9: =C9*0.07065 -> 4.9455 | C9: 70 | D9: 0.3 | E9: 0.29 | F9: =IFERROR((D9+E9)/2," ") -> 0.295 | G9: =F9-$F$7 -> 0.295 | H9: K30=196 MN/㎥ 이상 | J9: 노상 | L9: 2계열 | P9: 0.1 | Q9: 0.1 | S9: =E9+P9 -> 0.39 | T9: =F9+Q9 -> 0.395
A10: =A9+TIME(,RAND()*1+(1-0),RAND()*10+5) -> 0.0023726852 | B10: =C10*0.07065 -> 7.41825 | C10: 105 | D10: 0.58 | E10: 0.49 | F10: =IFERROR((D10+E10)/2," ") -> 0.535 | G10: =F10-$F$7 -> 0.535 | K10: X | L10: 0 | M10: =K13 -> 571 | P10: 0.1 | Q10: 0.1 | S10: =E10+P10 -> 0.59 | T10: =F10+Q10 -> 0.635
A11: =A10+TIME(,RAND()*1+(1-0),RAND()*10+5) -> 0.0031365741 | B11: =C11*0.07065 -> 9.891 | C11: 140 | D11: 0.77 | E11: 0.72 | F11: =IFERROR((D11+E11)/2," ") -> 0.745 | G11: =F11-$F$7 -> 0.745 | H11: K30=294 MN/㎥ 이상 | J11: 선택층 | K11: Y | L11: 2.5 | M11: 2.5 | P11: 0.1 | Q11: 0.1 | S11: =E11+P11 -> 0.82 | T11: =F11+Q11 -> 0.845
A12: =A11+TIME(,RAND()*1+(1-0),RAND()*10+10) -> 0.0040162037 | B12: =C12*0.07065 -> 12.36375 | C12: 175 | D12: 0.92 | E12: 0.9 | F12: =IFERROR((D12+E12)/2," ") -> 0.91 | G12: =F12-$F$7 -> 0.91 | K12: DATA입력↓ | L12: 3계열 | P12: 0.1 | Q12: 0.1 | S12: =E12+P12 -> 1 | T12: =F12+Q12 -> 1.01
A13: =A12+TIME(,RAND()*1+(1-0),RAND()*10+10) -> 0.0048842593 | B13: =C13*0.07065 -> 14.8365 | C13: 210 | D13: 1.07 | E13: 1.03 | F13: =IFERROR((D13+E13)/2," ") -> 1.05 | G13: =F13-$F$7 -> 1.05 | H13: K30=294 MN/㎥ 이상 | J13: 보조기층 | K13: 571 | L13: =M10 -> 571 | M13: =L13 -> 571 | P13: 0.1 | Q13: 0.1 | S13: =E13+P13 -> 1.13 | T13: =F13+Q13 -> 1.15
A14: =A13+TIME(,RAND()*1+(1-0),RAND()*10+10) -> 0.0057407407 | B14: =C14*0.07065 -> 17.30925 | C14: 245 | D14: 1.19 | E14: 1.12 | F14: =IFERROR((D14+E14)/2," ") -> 1.155 | G14: =F14-$F$7 -> 1.155 | K14: =K13/2.5 -> 228.4 | L14: 2.5 | M14: 0 | P14: 0.1 | Q14: 0.1 | S14: =E14+P14 -> 1.22 | T14: =F14+Q14 -> 1.255
A15: =A14+TIME(,RAND()*1+(1-0),RAND()*10+10) -> 0.0066087963 | B15: =C15*0.07065 -> 19.782 | C15: 280 | D15: 1.29 | E15: 1.28 | F15: =IFERROR((D15+E15)/2," ") -> 1.285 | G15: =F15-$F$7 -> 1.285 | H15: K30=294 MN/㎥ 이상 | J15: 뒷채움 | K15: =ROUND(K14,1)*1.3 -> 296.92 | N15: 1/100 | P15: 0.1 | Q15: 0.1 | S15: =E15+P15 -> 1.38 | T15: =F15+Q15 -> 1.385
A16: =A15+TIME(,RAND()*1+(1-0),RAND()*10+10) -> 0.0074652778 | B16: =C16*0.07065 -> 22.25475 | C16: 315 | D16: 1.42 | E16: 1.4 | F16: =IFERROR((D16+E16)/2," ") -> 1.41 | G16: =F16-$F$7 -> 1.41 | L16: 계산기 | M16: 기준침하량 | N16: 250
A17: =A16+TIME(,RAND()*1+(1-0),RAND()*10+10) -> 0.0083101852 | B17: =C17*0.07065 -> 24.7275 | C17: 350 | D17: 1.67 | E17: 1.52 | F17: =IFERROR((D17+E17)/2," ") -> 1.595 | G17: =F17-$F$7 -> 1.595 | H17: K30=196 MN/㎥ 이상 | J17: 암성토 | M17: 전(1) | N17: 후(2)
A18: =A17+TIME(,RAND()*1+(1-0),RAND()*10+10) -> 0.0091550926 | B18: =C18*0.07065 -> 27.20025 | C18: 385 | D18: 1.83 | E18: 1.66 | F18: =IFERROR((D18+E18)/2," ") -> 1.745 | G18: =F18-$F$7 -> 1.745 | L18: 침하량(y) | M18: 244 | N18: 257
A19: =A18+TIME(,RAND()*1+(1-0),RAND()*10+10) -> 0.0099884259 | B19: =C19*0.07065 -> 29.673 | C19: 420 | D19: 2.07 | E19: 1.79 | F19: =IFERROR((D19+E19)/2," ") -> 1.93 | G19: =F19-$F$7 -> 1.93 | H19: DATA 분석 | L19: 하중강도(x) | M19: 840 | N19: 875
A20: =A19+TIME(,RAND()*1+(1-0),RAND()*10+10) -> 0.010856481 | B20: =C20*0.07065 -> 32.14575 | C20: 455 | D20: 2.2 | E20: 1.9 | F20: =IFERROR((D20+E20)/2," ") -> 2.05 | G20: =F20-$F$7 -> 2.05 | L20: 결 과 | M20: =M19+((N16-M18)/((N18-M18)/(N19-M19))) -> 856.15385
A21: =A20+TIME(,RAND()*1+(1-0),RAND()*10+10) -> 0.011701389 | B21: =C21*0.07065 -> 34.6185 | C21: 490 | D21: 2.33 | E21: 2.03 | F21: =IFERROR((D21+E21)/2," ") -> 2.18 | G21: =F21-$F$7 -> 2.18 | H21: ="K30 = "&ROUND(K13,1)&"÷2.5" -> K30 = 571÷2.5 | L21: K30 | M21: =M20/N16*100 -> 342.46154
A22: =A21+TIME(,RAND()*1+(1-0),RAND()*10+10) -> 0.012534722 | B22: =C22*0.07065 -> 37.09125 | C22: 525 | D22: 2.559 | E22: 2.14 | F22: =IFERROR((D22+E22)/2," ") -> 2.3495 | G22: =F22-$F$7 -> 2.3495
A23: =A22+TIME(,RAND()*1+(1-0),RAND()*10+10) -> 0.013391204 | B23: =C23*0.07065 -> 39.564 | C23: 560 | D23: 2.7 | E23: 2.22 | F23: =IFERROR((D23+E23)/2," ") -> 2.46 | G23: =F23-$F$7 -> 2.46 | H23: =K14 -> 228.4
A24: =A23+TIME(,RAND()*1+(1-0),RAND()*10+10) -> 0.014201389 | B24: =C24*0.07065 -> 42.03675 | C24: 595 | D24: 2.79 | E24: 2.39 | F24: =IFERROR((D24+E24)/2," ") -> 2.59 | G24: =F24-$F$7 -> 2.59
A25: =A24+TIME(,RAND()*1+(1-0),RAND()*10+10) -> 0.015081019 | B25: =C25*0.07065 -> 44.5095 | C25: 630 | D25: 2.85 | E25: 2.48 | F25: =IFERROR((D25+E25)/2," ") -> 2.665 | G25: =F25-$F$7 -> 2.665
H26: ="K30 = "&ROUND(K14,1)&"×1.3" -> K30 = 228.4×1.3
H28: =K14*1.3 -> 296.92
H32: 시험 결과
H34: =" ∴ "&ROUND(H23,1)&" ＞ 147 MN/㎥ " -> ∴ 228.4 ＞ 147 MN/㎥
H36: 기준에 적합
A38: ■ 비고 - 재하판 안정을 위해 미리 하중 강도 35kN/㎡ 상당의 하중을 가한 후 제거 - 하중 강도가 35kN/㎡씩 되도록 하중을 단계적으로 증가 - 하중에 의한 침하의 진행이 멈추면 하중계와 변위계 눈금 측정 * 침하 진행이 멈추는 경우의 판단 기준 : 1분간의 침하량이 그 하중 강도에 의한 그 단계의 누적 침하량의 1% 이하 일때 - 쌓기의 치수가 300mm 이하이므로 직경 300mm 재하판 사용 - 상부 아스팔트 콘크리트 포장으로 침하량 2.5mm 적용
A43: 시험자 : 윤 정 필 (인) 확인자 : 백 귀 석 (인) 건설사업관리기술인 : 금 동 훈 (인)
A45: 사 진 대 지
A46: 공사명 : 양촌·용정지구 일반산업단지 부지조성공사
A54: 1 | C54: 내 용
C55: 위 치
C56: 일 시
A64: 2 | C64: 내 용
C65: 위 치
C66: 일 시

Sheet 48
A1: 평 판 재 하 시 험 | L1: K30=2.2×K75 K30=1.3×K40
A2: 공 사 명 : | B2: 진천메가폴리스 산업단지 조성사업 | F2: 시험일자 : | G2: =List!B51 -> 46217 | K2: 시험번호
A3: 시험번호 : | B3: =List!A51 -> 48 | F3: 위 치 : | G3: =List!C51 -> 중로(집) 3-16 (No.36 ~ No.50, 좌측) 노체 21단(63층) | K3: 1 | L3: 지반반력계수 환산
A4: 재하조건 | B4: 재하판 지름 : | C4: 300 | D4: 평판면적 : | E4: =30*30/4*3.14 -> 706.5 | F4: 초기하중 : | G4: 35kN/㎡ | H4: KS F 2310
A5: 시간 min - s | B5: 하중 | D5: 변위계의 눈금(mm) | G5: 침하량 (mm) | H5: 적 용 시 방 기 준 (콘크리트포장)
B6: 전하중 (kN) | C6: 재하응력 (kN/㎡) | D6: 왼쪽 | E6: 오른쪽 | F6: 평균
A7: 0 | B7: 0 | C7: 0 | D7: 0 | E7: 0 | F7: =(D7+E7)/2 -> 0 | G7: 0 | H7: K30=147 MN/㎥ 이상 | J7: 노체
A8: =TIME(,RAND()*1+(1-0),RAND()*10+4) -> 0.00081018519 | B8: =C8*0.07065 -> 2.47275 | C8: 35 | D8: 0.32 | E8: 0.35 | F8: =IFERROR((D8+E8)/2," ") -> 0.335 | G8: =F8-F7 -> 0.335 | P8: 0.1 | Q8: 0.1 | S8: =E8+P8 -> 0.45 | T8: =F8+Q8 -> 0.435
A9: =A8+TIME(,RAND()*1+(1-0),RAND()*10+10) -> 0.0016666667 | B9: =C9*0.07065 -> 4.9455 | C9: 70 | D9: 0.55 | E9: 0.57 | F9: =IFERROR((D9+E9)/2," ") -> 0.56 | G9: =F9-$F$7 -> 0.56 | H9: K30=196 MN/㎥ 이상 | J9: 노상 | L9: 2계열 | P9: 0.1 | Q9: 0.1 | S9: =E9+P9 -> 0.67 | T9: =F9+Q9 -> 0.66
A10: =A9+TIME(,RAND()*1+(1-0),RAND()*10+5) -> 0.0025115741 | B10: =C10*0.07065 -> 7.41825 | C10: 105 | D10: 0.68 | E10: 0.7 | F10: =IFERROR((D10+E10)/2," ") -> 0.69 | G10: =F10-$F$7 -> 0.69 | K10: X | L10: 0 | M10: =K13 -> 577 | P10: 0.1 | Q10: 0.1 | S10: =E10+P10 -> 0.8 | T10: =F10+Q10 -> 0.79
A11: =A10+TIME(,RAND()*1+(1-0),RAND()*10+5) -> 0.0033680556 | B11: =C11*0.07065 -> 9.891 | C11: 140 | D11: 0.78 | E11: 0.81 | F11: =IFERROR((D11+E11)/2," ") -> 0.795 | G11: =F11-$F$7 -> 0.795 | H11: K30=294 MN/㎥ 이상 | J11: 선택층 | K11: Y | L11: 2.5 | M11: 2.5 | P11: 0.1 | Q11: 0.1 | S11: =E11+P11 -> 0.91 | T11: =F11+Q11 -> 0.895
A12: =A11+TIME(,RAND()*1+(1-0),RAND()*10+10) -> 0.004212963 | B12: =C12*0.07065 -> 12.36375 | C12: 175 | D12: 0.87 | E12: 0.98 | F12: =IFERROR((D12+E12)/2," ") -> 0.925 | G12: =F12-$F$7 -> 0.925 | K12: DATA입력↓ | L12: 3계열 | P12: 0.1 | Q12: 0.1 | S12: =E12+P12 -> 1.08 | T12: =F12+Q12 -> 1.025
A13: =A12+TIME(,RAND()*1+(1-0),RAND()*10+10) -> 0.0050231481 | B13: =C13*0.07065 -> 14.8365 | C13: 210 | D13: 1 | E13: 1.07 | F13: =IFERROR((D13+E13)/2," ") -> 1.035 | G13: =F13-$F$7 -> 1.035 | H13: K30=294 MN/㎥ 이상 | J13: 보조기층 | K13: 577 | L13: =M10 -> 577 | M13: =L13 -> 577 | P13: 0.1 | Q13: 0.1 | S13: =E13+P13 -> 1.17 | T13: =F13+Q13 -> 1.135
A14: =A13+TIME(,RAND()*1+(1-0),RAND()*10+10) -> 0.0058449074 | B14: =C14*0.07065 -> 17.30925 | C14: 245 | D14: 1.11 | E14: 1.26 | F14: =IFERROR((D14+E14)/2," ") -> 1.185 | G14: =F14-$F$7 -> 1.185 | K14: =K13/2.5 -> 230.8 | L14: 2.5 | M14: 0 | P14: 0.1 | Q14: 0.1 | S14: =E14+P14 -> 1.36 | T14: =F14+Q14 -> 1.285
A15: =A14+TIME(,RAND()*1+(1-0),RAND()*10+10) -> 0.0067361111 | B15: =C15*0.07065 -> 19.782 | C15: 280 | D15: 1.22 | E15: 1.38 | F15: =IFERROR((D15+E15)/2," ") -> 1.3 | G15: =F15-$F$7 -> 1.3 | H15: K30=294 MN/㎥ 이상 | J15: 뒷채움 | K15: =ROUND(K14,1)*1.3 -> 300.04 | N15: 1/100 | P15: 0.1 | Q15: 0.1 | S15: =E15+P15 -> 1.48 | T15: =F15+Q15 -> 1.4
A16: =A15+TIME(,RAND()*1+(1-0),RAND()*10+10) -> 0.0075810185 | B16: =C16*0.07065 -> 22.25475 | C16: 315 | D16: 1.33 | E16: 1.52 | F16: =IFERROR((D16+E16)/2," ") -> 1.425 | G16: =F16-$F$7 -> 1.425 | L16: 계산기 | M16: 기준침하량 | N16: 250
A17: =A16+TIME(,RAND()*1+(1-0),RAND()*10+10) -> 0.0084722222 | B17: =C17*0.07065 -> 24.7275 | C17: 350 | D17: 1.46 | E17: 1.72 | F17: =IFERROR((D17+E17)/2," ") -> 1.59 | G17: =F17-$F$7 -> 1.59 | H17: K30=196 MN/㎥ 이상 | J17: 암성토 | M17: 전(1) | N17: 후(2)
A18: =A17+TIME(,RAND()*1+(1-0),RAND()*10+10) -> 0.0093171296 | B18: =C18*0.07065 -> 27.20025 | C18: 385 | D18: 1.55 | E18: 1.94 | F18: =IFERROR((D18+E18)/2," ") -> 1.745 | G18: =F18-$F$7 -> 1.745 | L18: 침하량(y) | M18: 244 | N18: 257
A19: =A18+TIME(,RAND()*1+(1-0),RAND()*10+10) -> 0.010208333 | B19: =C19*0.07065 -> 29.673 | C19: 420 | D19: 1.68 | E19: 2.01 | F19: =IFERROR((D19+E19)/2," ") -> 1.845 | G19: =F19-$F$7 -> 1.845 | H19: DATA 분석 | L19: 하중강도(x) | M19: 840 | N19: 875
A20: =A19+TIME(,RAND()*1+(1-0),RAND()*10+10) -> 0.011018519 | B20: =C20*0.07065 -> 32.14575 | C20: 455 | D20: 1.78 | E20: 2.17 | F20: =IFERROR((D20+E20)/2," ") -> 1.975 | G20: =F20-$F$7 -> 1.975 | L20: 결 과 | M20: =M19+((N16-M18)/((N18-M18)/(N19-M19))) -> 856.15385
A21: =A20+TIME(,RAND()*1+(1-0),RAND()*10+10) -> 0.011909722 | B21: =C21*0.07065 -> 34.6185 | C21: 490 | D21: 1.97 | E21: 2.28 | F21: =IFERROR((D21+E21)/2," ") -> 2.125 | G21: =F21-$F$7 -> 2.125 | H21: ="K30 = "&ROUND(K13,1)&"÷2.5" -> K30 = 577÷2.5 | L21: K30 | M21: =M20/N16*100 -> 342.46154
A22: =A21+TIME(,RAND()*1+(1-0),RAND()*10+10) -> 0.012719907 | B22: =C22*0.07065 -> 37.09125 | C22: 525 | D22: 2.17 | E22: 2.4 | F22: =IFERROR((D22+E22)/2," ") -> 2.285 | G22: =F22-$F$7 -> 2.285
A23: =A22+TIME(,RAND()*1+(1-0),RAND()*10+10) -> 0.013530093 | B23: =C23*0.07065 -> 39.564 | C23: 560 | D23: 2.29 | E23: 2.65 | F23: =IFERROR((D23+E23)/2," ") -> 2.47 | G23: =F23-$F$7 -> 2.47 | H23: =K14 -> 230.8
A24: =A23+TIME(,RAND()*1+(1-0),RAND()*10+10) -> 0.014363426 | B24: =C24*0.07065 -> 42.03675 | C24: 595 | D24: 2.36 | E24: 2.78 | F24: =IFERROR((D24+E24)/2," ") -> 2.57 | G24: =F24-$F$7 -> 2.57
A25: =A24+TIME(,RAND()*1+(1-0),RAND()*10+10) -> 0.015173611 | B25: =C25*0.07065 -> 44.5095 | C25: 630 | D25: 2.48 | E25: 2.94 | F25: =IFERROR((D25+E25)/2," ") -> 2.71 | G25: =F25-$F$7 -> 2.71
H26: ="K30 = "&ROUND(K14,1)&"×1.3" -> K30 = 230.8×1.3
H28: =K14*1.3 -> 300.04
H32: 시험 결과
H34: =" ∴ "&ROUND(H23,1)&" ＞ 147 MN/㎥ " -> ∴ 230.8 ＞ 147 MN/㎥
H36: 기준에 적합
A38: ■ 비고 - 재하판 안정을 위해 미리 하중 강도 35kN/㎡ 상당의 하중을 가한 후 제거 - 하중 강도가 35kN/㎡씩 되도록 하중을 단계적으로 증가 - 하중에 의한 침하의 진행이 멈추면 하중계와 변위계 눈금 측정 * 침하 진행이 멈추는 경우의 판단 기준 : 1분간의 침하량이 그 하중 강도에 의한 그 단계의 누적 침하량의 1% 이하 일때 - 쌓기의 치수가 300mm 이하이므로 직경 300mm 재하판 사용 - 상부 아스팔트 콘크리트 포장으로 침하량 2.5mm 적용
A43: 시험자 : 윤 정 필 (인) 확인자 : 백 귀 석 (인) 건설사업관리기술인 : 금 동 훈 (인)
A45: 사 진 대 지
A46: 공사명 : 양촌·용정지구 일반산업단지 부지조성공사
A54: 1 | C54: 내 용
C55: 위 치
C56: 일 시
A64: 2 | C64: 내 용
C65: 위 치
C66: 일 시

Sheet 47
A1: 평 판 재 하 시 험 | L1: K30=2.2×K75 K30=1.3×K40
A2: 공 사 명 : | B2: 진천메가폴리스 산업단지 조성사업 | F2: 시험일자 : | G2: =List!B50 -> 46199 | K2: 시험번호
A3: 시험번호 : | B3: =List!A50 -> 47 | F3: 위 치 : | G3: =List!C50 -> 중로(집) 3-16 (No.36 ~ No.50) 노체 20단(60층) - 2회 | K3: 1 | L3: 지반반력계수 환산
A4: 재하조건 | B4: 재하판 지름 : | C4: 300 | D4: 평판면적 : | E4: =30*30/4*3.14 -> 706.5 | F4: 초기하중 : | G4: 35kN/㎡ | H4: KS F 2310
A5: 시간 min - s | B5: 하중 | D5: 변위계의 눈금(mm) | G5: 침하량 (mm) | H5: 적 용 시 방 기 준 (콘크리트포장)
B6: 전하중 (kN) | C6: 재하응력 (kN/㎡) | D6: 왼쪽 | E6: 오른쪽 | F6: 평균
A7: 0 | B7: 0 | C7: 0 | D7: 0 | E7: 0 | F7: =(D7+E7)/2 -> 0 | G7: 0 | H7: K30=147 MN/㎥ 이상 | J7: 노체
A8: =TIME(,RAND()*1+(1-0),RAND()*10+4) -> 0.00074074074 | B8: =C8*0.07065 -> 2.47275 | C8: 35 | D8: 0.2 | E8: 0.35 | F8: =IFERROR((D8+E8)/2," ") -> 0.275 | G8: =F8-F7 -> 0.275 | P8: 0.1 | Q8: 0.1 | S8: =E8+P8 -> 0.45 | T8: =F8+Q8 -> 0.375
A9: =A8+TIME(,RAND()*1+(1-0),RAND()*10+10) -> 0.0016203704 | B9: =C9*0.07065 -> 4.9455 | C9: 70 | D9: 0.3 | E9: 0.73 | F9: =IFERROR((D9+E9)/2," ") -> 0.515 | G9: =F9-$F$7 -> 0.515 | H9: K30=196 MN/㎥ 이상 | J9: 노상 | L9: 2계열 | P9: 0.1 | Q9: 0.1 | S9: =E9+P9 -> 0.83 | T9: =F9+Q9 -> 0.615
A10: =A9+TIME(,RAND()*1+(1-0),RAND()*10+5) -> 0.0023958333 | B10: =C10*0.07065 -> 7.41825 | C10: 105 | D10: 0.69 | E10: 1.02 | F10: =IFERROR((D10+E10)/2," ") -> 0.855 | G10: =F10-$F$7 -> 0.855 | K10: X | L10: 0 | M10: =K13 -> 562 | P10: 0.1 | Q10: 0.1 | S10: =E10+P10 -> 1.12 | T10: =F10+Q10 -> 0.955
A11: =A10+TIME(,RAND()*1+(1-0),RAND()*10+5) -> 0.0031828704 | B11: =C11*0.07065 -> 9.891 | C11: 140 | D11: 0.83 | E11: 1.15 | F11: =IFERROR((D11+E11)/2," ") -> 0.99 | G11: =F11-$F$7 -> 0.99 | H11: K30=294 MN/㎥ 이상 | J11: 선택층 | K11: Y | L11: 2.5 | M11: 2.5 | P11: 0.1 | Q11: 0.1 | S11: =E11+P11 -> 1.25 | T11: =F11+Q11 -> 1.09
A12: =A11+TIME(,RAND()*1+(1-0),RAND()*10+10) -> 0.0040046296 | B12: =C12*0.07065 -> 12.36375 | C12: 175 | D12: 0.96 | E12: 1.28 | F12: =IFERROR((D12+E12)/2," ") -> 1.12 | G12: =F12-$F$7 -> 1.12 | K12: DATA입력↓ | L12: 3계열 | P12: 0.1 | Q12: 0.1 | S12: =E12+P12 -> 1.38 | T12: =F12+Q12 -> 1.22
A13: =A12+TIME(,RAND()*1+(1-0),RAND()*10+10) -> 0.004849537 | B13: =C13*0.07065 -> 14.8365 | C13: 210 | D13: 1.11 | E13: 1.39 | F13: =IFERROR((D13+E13)/2," ") -> 1.25 | G13: =F13-$F$7 -> 1.25 | H13: K30=294 MN/㎥ 이상 | J13: 보조기층 | K13: 562 | L13: =M10 -> 562 | M13: =L13 -> 562 | P13: 0.1 | Q13: 0.1 | S13: =E13+P13 -> 1.49 | T13: =F13+Q13 -> 1.35
A14: =A13+TIME(,RAND()*1+(1-0),RAND()*10+10) -> 0.0056597222 | B14: =C14*0.07065 -> 17.30925 | C14: 245 | D14: 1.31 | E14: 1.52 | F14: =IFERROR((D14+E14)/2," ") -> 1.415 | G14: =F14-$F$7 -> 1.415 | K14: =K13/2.5 -> 224.8 | L14: 2.5 | M14: 0 | P14: 0.1 | Q14: 0.1 | S14: =E14+P14 -> 1.62 | T14: =F14+Q14 -> 1.515
A15: =A14+TIME(,RAND()*1+(1-0),RAND()*10+10) -> 0.0065046296 | B15: =C15*0.07065 -> 19.782 | C15: 280 | D15: 1.49 | E15: 1.64 | F15: =IFERROR((D15+E15)/2," ") -> 1.565 | G15: =F15-$F$7 -> 1.565 | H15: K30=294 MN/㎥ 이상 | J15: 뒷채움 | K15: =ROUND(K14,1)*1.3 -> 292.24 | N15: 1/100 | P15: 0.1 | Q15: 0.1 | S15: =E15+P15 -> 1.74 | T15: =F15+Q15 -> 1.665
A16: =A15+TIME(,RAND()*1+(1-0),RAND()*10+10) -> 0.0074189815 | B16: =C16*0.07065 -> 22.25475 | C16: 315 | D16: 1.57 | E16: 1.75 | F16: =IFERROR((D16+E16)/2," ") -> 1.66 | G16: =F16-$F$7 -> 1.66 | L16: 계산기 | M16: 기준침하량 | N16: 250
A17: =A16+TIME(,RAND()*1+(1-0),RAND()*10+10) -> 0.0082986111 | B17: =C17*0.07065 -> 24.7275 | C17: 350 | D17: 1.71 | E17: 1.87 | F17: =IFERROR((D17+E17)/2," ") -> 1.79 | G17: =F17-$F$7 -> 1.79 | H17: K30=196 MN/㎥ 이상 | J17: 암성토 | M17: 전(1) | N17: 후(2)
A18: =A17+TIME(,RAND()*1+(1-0),RAND()*10+10) -> 0.0091550926 | B18: =C18*0.07065 -> 27.20025 | C18: 385 | D18: 1.8 | E18: 2.03 | F18: =IFERROR((D18+E18)/2," ") -> 1.915 | G18: =F18-$F$7 -> 1.915 | L18: 침하량(y) | M18: 244 | N18: 257
A19: =A18+TIME(,RAND()*1+(1-0),RAND()*10+10) -> 0.0099652778 | B19: =C19*0.07065 -> 29.673 | C19: 420 | D19: 1.94 | E19: 2.14 | F19: =IFERROR((D19+E19)/2," ") -> 2.04 | G19: =F19-$F$7 -> 2.04 | H19: DATA 분석 | L19: 하중강도(x) | M19: 840 | N19: 875
A20: =A19+TIME(,RAND()*1+(1-0),RAND()*10+10) -> 0.010844907 | B20: =C20*0.07065 -> 32.14575 | C20: 455 | D20: 2.05 | E20: 2.21 | F20: =IFERROR((D20+E20)/2," ") -> 2.13 | G20: =F20-$F$7 -> 2.13 | L20: 결 과 | M20: =M19+((N16-M18)/((N18-M18)/(N19-M19))) -> 856.15385
A21: =A20+TIME(,RAND()*1+(1-0),RAND()*10+10) -> 0.011655093 | B21: =C21*0.07065 -> 34.6185 | C21: 490 | D21: 2.17 | E21: 2.37 | F21: =IFERROR((D21+E21)/2," ") -> 2.27 | G21: =F21-$F$7 -> 2.27 | H21: ="K30 = "&ROUND(K13,1)&"÷2.5" -> K30 = 562÷2.5 | L21: K30 | M21: =M20/N16*100 -> 342.46154
A22: =A21+TIME(,RAND()*1+(1-0),RAND()*10+10) -> 0.012511574 | B22: =C22*0.07065 -> 37.09125 | C22: 525 | D22: 2.29 | E22: 2.48 | F22: =IFERROR((D22+E22)/2," ") -> 2.385 | G22: =F22-$F$7 -> 2.385
A23: =A22+TIME(,RAND()*1+(1-0),RAND()*10+10) -> 0.013333333 | B23: =C23*0.07065 -> 39.564 | C23: 560 | D23: 2.42 | E23: 2.6 | F23: =IFERROR((D23+E23)/2," ") -> 2.51 | G23: =F23-$F$7 -> 2.51 | H23: =K14 -> 224.8
A24: =A23+TIME(,RAND()*1+(1-0),RAND()*10+10) -> 0.014212963 | B24: =C24*0.07065 -> 42.03675 | C24: 595 | D24: 2.54 | E24: 2.68 | F24: =IFERROR((D24+E24)/2," ") -> 2.61 | G24: =F24-$F$7 -> 2.61
A25: =A24+TIME(,RAND()*1+(1-0),RAND()*10+10) -> 0.015046296 | B25: =C25*0.07065 -> 44.5095 | C25: 630 | D25: 2.63 | E25: 2.75 | F25: =IFERROR((D25+E25)/2," ") -> 2.69 | G25: =F25-$F$7 -> 2.69
H26: ="K30 = "&ROUND(K14,1)&"×1.3" -> K30 = 224.8×1.3
H28: =K14*1.3 -> 292.24
H32: 시험 결과
H34: =" ∴ "&ROUND(H23,1)&" ＞ 147 MN/㎥ " -> ∴ 224.8 ＞ 147 MN/㎥
H36: 기준에 적합
A38: ■ 비고 - 재하판 안정을 위해 미리 하중 강도 35kN/㎡ 상당의 하중을 가한 후 제거 - 하중 강도가 35kN/㎡씩 되도록 하중을 단계적으로 증가 - 하중에 의한 침하의 진행이 멈추면 하중계와 변위계 눈금 측정 * 침하 진행이 멈추는 경우의 판단 기준 : 1분간의 침하량이 그 하중 강도에 의한 그 단계의 누적 침하량의 1% 이하 일때 - 쌓기의 치수가 300mm 이하이므로 직경 300mm 재하판 사용 - 상부 아스팔트 콘크리트 포장으로 침하량 2.5mm 적용
A43: 시험자 : 문 정 수 (인) 확인자 : 백 귀 석 (인) 건설사업관리기술인 : 금 동 훈 (인)
A45: 사 진 대 지
A46: 공사명 : 양촌·용정지구 일반산업단지 부지조성공사
A54: 1 | C54: 내 용
C55: 위 치
C56: 일 시
A64: 2 | C64: 내 용
C65: 위 치
C66: 일 시

Sheet 46
A1: 평 판 재 하 시 험 | L1: K30=2.2×K75 K30=1.3×K40
A2: 공 사 명 : | B2: 진천메가폴리스 산업단지 조성사업 | F2: 시험일자 : | G2: =List!B49 -> 46199 | K2: 시험번호
A3: 시험번호 : | B3: =List!A49 -> 46 | F3: 위 치 : | G3: =List!C49 -> 중로(집) 3-16 (No.36 ~ No.50) 노체 20단(60층) - 1회 | K3: 1 | L3: 지반반력계수 환산
A4: 재하조건 | B4: 재하판 지름 : | C4: 300 | D4: 평판면적 : | E4: =30*30/4*3.14 -> 706.5 | F4: 초기하중 : | G4: 35kN/㎡ | H4: KS F 2310
A5: 시간 min - s | B5: 하중 | D5: 변위계의 눈금(mm) | G5: 침하량 (mm) | H5: 적 용 시 방 기 준 (콘크리트포장)
B6: 전하중 (kN) | C6: 재하응력 (kN/㎡) | D6: 왼쪽 | E6: 오른쪽 | F6: 평균
A7: 0 | B7: 0 | C7: 0 | D7: 0 | E7: 0 | F7: =(D7+E7)/2 -> 0 | G7: 0 | H7: K30=147 MN/㎥ 이상 | J7: 노체
A8: =TIME(,RAND()*1+(1-0),RAND()*10+4) -> 0.00082175926 | B8: =C8*0.07065 -> 2.47275 | C8: 35 | D8: 0.35 | E8: 0.22 | F8: =IFERROR((D8+E8)/2," ") -> 0.285 | G8: =F8-F7 -> 0.285 | P8: 0.1 | Q8: 0.1 | S8: =E8+P8 -> 0.32 | T8: =F8+Q8 -> 0.385
A9: =A8+TIME(,RAND()*1+(1-0),RAND()*10+10) -> 0.0016782407 | B9: =C9*0.07065 -> 4.9455 | C9: 70 | D9: 0.7 | E9: 0.34 | F9: =IFERROR((D9+E9)/2," ") -> 0.52 | G9: =F9-$F$7 -> 0.52 | H9: K30=196 MN/㎥ 이상 | J9: 노상 | L9: 2계열 | P9: 0.1 | Q9: 0.1 | S9: =E9+P9 -> 0.44 | T9: =F9+Q9 -> 0.62
A10: =A9+TIME(,RAND()*1+(1-0),RAND()*10+5) -> 0.0025231481 | B10: =C10*0.07065 -> 7.41825 | C10: 105 | D10: 0.87 | E10: 0.46 | F10: =IFERROR((D10+E10)/2," ") -> 0.665 | G10: =F10-$F$7 -> 0.665 | K10: X | L10: 0 | M10: =K13 -> 576 | P10: 0.1 | Q10: 0.1 | S10: =E10+P10 -> 0.56 | T10: =F10+Q10 -> 0.765
A11: =A10+TIME(,RAND()*1+(1-0),RAND()*10+5) -> 0.0033564815 | B11: =C11*0.07065 -> 9.891 | C11: 140 | D11: 1.12 | E11: 0.59 | F11: =IFERROR((D11+E11)/2," ") -> 0.855 | G11: =F11-$F$7 -> 0.855 | H11: K30=294 MN/㎥ 이상 | J11: 선택층 | K11: Y | L11: 2.5 | M11: 2.5 | P11: 0.1 | Q11: 0.1 | S11: =E11+P11 -> 0.69 | T11: =F11+Q11 -> 0.955
A12: =A11+TIME(,RAND()*1+(1-0),RAND()*10+10) -> 0.0041782407 | B12: =C12*0.07065 -> 12.36375 | C12: 175 | D12: 1.22 | E12: 0.74 | F12: =IFERROR((D12+E12)/2," ") -> 0.98 | G12: =F12-$F$7 -> 0.98 | K12: DATA입력↓ | L12: 3계열 | P12: 0.1 | Q12: 0.1 | S12: =E12+P12 -> 0.84 | T12: =F12+Q12 -> 1.08
A13: =A12+TIME(,RAND()*1+(1-0),RAND()*10+10) -> 0.0050694444 | B13: =C13*0.07065 -> 14.8365 | C13: 210 | D13: 1.35 | E13: 0.9 | F13: =IFERROR((D13+E13)/2," ") -> 1.125 | G13: =F13-$F$7 -> 1.125 | H13: K30=294 MN/㎥ 이상 | J13: 보조기층 | K13: 576 | L13: =M10 -> 576 | M13: =L13 -> 576 | P13: 0.1 | Q13: 0.1 | S13: =E13+P13 -> 1 | T13: =F13+Q13 -> 1.225
A14: =A13+TIME(,RAND()*1+(1-0),RAND()*10+10) -> 0.0059606481 | B14: =C14*0.07065 -> 17.30925 | C14: 245 | D14: 1.49 | E14: 1.12 | F14: =IFERROR((D14+E14)/2," ") -> 1.305 | G14: =F14-$F$7 -> 1.305 | K14: =K13/2.5 -> 230.4 | L14: 2.5 | M14: 0 | P14: 0.1 | Q14: 0.1 | S14: =E14+P14 -> 1.22 | T14: =F14+Q14 -> 1.405
A15: =A14+TIME(,RAND()*1+(1-0),RAND()*10+10) -> 0.0067824074 | B15: =C15*0.07065 -> 19.782 | C15: 280 | D15: 1.61 | E15: 1.23 | F15: =IFERROR((D15+E15)/2," ") -> 1.42 | G15: =F15-$F$7 -> 1.42 | H15: K30=294 MN/㎥ 이상 | J15: 뒷채움 | K15: =ROUND(K14,1)*1.3 -> 299.52 | N15: 1/100 | P15: 0.1 | Q15: 0.1 | S15: =E15+P15 -> 1.33 | T15: =F15+Q15 -> 1.52
A16: =A15+TIME(,RAND()*1+(1-0),RAND()*10+10) -> 0.0076736111 | B16: =C16*0.07065 -> 22.25475 | C16: 315 | D16: 1.72 | E16: 1.37 | F16: =IFERROR((D16+E16)/2," ") -> 1.545 | G16: =F16-$F$7 -> 1.545 | L16: 계산기 | M16: 기준침하량 | N16: 250
A17: =A16+TIME(,RAND()*1+(1-0),RAND()*10+10) -> 0.0085648148 | B17: =C17*0.07065 -> 24.7275 | C17: 350 | D17: 1.89 | E17: 1.49 | F17: =IFERROR((D17+E17)/2," ") -> 1.69 | G17: =F17-$F$7 -> 1.69 | H17: K30=196 MN/㎥ 이상 | J17: 암성토 | M17: 전(1) | N17: 후(2)
A18: =A17+TIME(,RAND()*1+(1-0),RAND()*10+10) -> 0.0093865741 | B18: =C18*0.07065 -> 27.20025 | C18: 385 | D18: 2 | E18: 1.57 | F18: =IFERROR((D18+E18)/2," ") -> 1.785 | G18: =F18-$F$7 -> 1.785 | L18: 침하량(y) | M18: 244 | N18: 257
A19: =A18+TIME(,RAND()*1+(1-0),RAND()*10+10) -> 0.010289352 | B19: =C19*0.07065 -> 29.673 | C19: 420 | D19: 2.13 | E19: 1.69 | F19: =IFERROR((D19+E19)/2," ") -> 1.91 | G19: =F19-$F$7 -> 1.91 | H19: DATA 분석 | L19: 하중강도(x) | M19: 840 | N19: 875
A20: =A19+TIME(,RAND()*1+(1-0),RAND()*10+10) -> 0.011134259 | B20: =C20*0.07065 -> 32.14575 | C20: 455 | D20: 2.26 | E20: 1.8 | F20: =IFERROR((D20+E20)/2," ") -> 2.03 | G20: =F20-$F$7 -> 2.03 | L20: 결 과 | M20: =M19+((N16-M18)/((N18-M18)/(N19-M19))) -> 856.15385
A21: =A20+TIME(,RAND()*1+(1-0),RAND()*10+10) -> 0.011967593 | B21: =C21*0.07065 -> 34.6185 | C21: 490 | D21: 2.41 | E21: 1.95 | F21: =IFERROR((D21+E21)/2," ") -> 2.18 | G21: =F21-$F$7 -> 2.18 | H21: ="K30 = "&ROUND(K13,1)&"÷2.5" -> K30 = 576÷2.5 | L21: K30 | M21: =M20/N16*100 -> 342.46154
A22: =A21+TIME(,RAND()*1+(1-0),RAND()*10+10) -> 0.012835648 | B22: =C22*0.07065 -> 37.09125 | C22: 525 | D22: 2.692 | E22: 2.05 | F22: =IFERROR((D22+E22)/2," ") -> 2.371 | G22: =F22-$F$7 -> 2.371
A23: =A22+TIME(,RAND()*1+(1-0),RAND()*10+10) -> 0.013668981 | B23: =C23*0.07065 -> 39.564 | C23: 560 | D23: 2.735 | E23: 2.18 | F23: =IFERROR((D23+E23)/2," ") -> 2.4575 | G23: =F23-$F$7 -> 2.4575 | H23: =K14 -> 230.4
A24: =A23+TIME(,RAND()*1+(1-0),RAND()*10+10) -> 0.014583333 | B24: =C24*0.07065 -> 42.03675 | C24: 595 | D24: 2.81 | E24: 2.35 | F24: =IFERROR((D24+E24)/2," ") -> 2.58 | G24: =F24-$F$7 -> 2.58
A25: =A24+TIME(,RAND()*1+(1-0),RAND()*10+10) -> 0.015486111 | B25: =C25*0.07065 -> 44.5095 | C25: 630 | D25: 2.88 | E25: 2.4 | F25: =IFERROR((D25+E25)/2," ") -> 2.64 | G25: =F25-$F$7 -> 2.64
H26: ="K30 = "&ROUND(K14,1)&"×1.3" -> K30 = 230.4×1.3
H28: =K14*1.3 -> 299.52
H32: 시험 결과
H34: =" ∴ "&ROUND(H23,1)&" ＞ 147 MN/㎥ " -> ∴ 230.4 ＞ 147 MN/㎥
H36: 기준에 적합
A38: ■ 비고 - 재하판 안정을 위해 미리 하중 강도 35kN/㎡ 상당의 하중을 가한 후 제거 - 하중 강도가 35kN/㎡씩 되도록 하중을 단계적으로 증가 - 하중에 의한 침하의 진행이 멈추면 하중계와 변위계 눈금 측정 * 침하 진행이 멈추는 경우의 판단 기준 : 1분간의 침하량이 그 하중 강도에 의한 그 단계의 누적 침하량의 1% 이하 일때 - 쌓기의 치수가 300mm 이하이므로 직경 300mm 재하판 사용 - 상부 아스팔트 콘크리트 포장으로 침하량 2.5mm 적용
A43: 시험자 : 문 정 수 (인) 확인자 : 백 귀 석 (인) 건설사업관리기술인 : 금 동 훈 (인)
A45: 사 진 대 지
A46: 공사명 : 양촌·용정지구 일반산업단지 부지조성공사
A54: 1 | C54: 내 용
C55: 위 치
C56: 일 시
A64: 2 | C64: 내 용
C65: 위 치
C66: 일 시

Sheet 45
A1: 평 판 재 하 시 험 | L1: K30=2.2×K75 K30=1.3×K40
A2: 공 사 명 : | B2: 진천메가폴리스 산업단지 조성사업 | F2: 시험일자 : | G2: =List!B48 -> 46195 | K2: 시험번호
A3: 시험번호 : | B3: =List!A48 -> 45 | F3: 위 치 : | G3: =List!C48 -> 중로(집) 3-16 (No.36 ~ No.50) 노체 19단(57층) - 2회 | K3: 1 | L3: 지반반력계수 환산
A4: 재하조건 | B4: 재하판 지름 : | C4: 300 | D4: 평판면적 : | E4: =30*30/4*3.14 -> 706.5 | F4: 초기하중 : | G4: 35kN/㎡ | H4: KS F 2310
A5: 시간 min - s | B5: 하중 | D5: 변위계의 눈금(mm) | G5: 침하량 (mm) | H5: 적 용 시 방 기 준 (콘크리트포장)
B6: 전하중 (kN) | C6: 재하응력 (kN/㎡) | D6: 왼쪽 | E6: 오른쪽 | F6: 평균
A7: 0 | B7: 0 | C7: 0 | D7: 0 | E7: 0 | F7: =(D7+E7)/2 -> 0 | G7: 0 | H7: K30=147 MN/㎥ 이상 | J7: 노체
A8: =TIME(,RAND()*1+(1-0),RAND()*10+4) -> 0.00079861111 | B8: =C8*0.07065 -> 2.47275 | C8: 35 | D8: 0.17 | E8: 0.31 | F8: =IFERROR((D8+E8)/2," ") -> 0.24 | G8: =F8-F7 -> 0.24 | P8: 0.1 | Q8: 0.1 | S8: =E8+P8 -> 0.41 | T8: =F8+Q8 -> 0.34
A9: =A8+TIME(,RAND()*1+(1-0),RAND()*10+10) -> 0.001712963 | B9: =C9*0.07065 -> 4.9455 | C9: 70 | D9: 0.34 | E9: 0.45 | F9: =IFERROR((D9+E9)/2," ") -> 0.395 | G9: =F9-$F$7 -> 0.395 | H9: K30=196 MN/㎥ 이상 | J9: 노상 | L9: 2계열 | P9: 0.1 | Q9: 0.1 | S9: =E9+P9 -> 0.55 | T9: =F9+Q9 -> 0.495
A10: =A9+TIME(,RAND()*1+(1-0),RAND()*10+5) -> 0.0025347222 | B10: =C10*0.07065 -> 7.41825 | C10: 105 | D10: 0.56 | E10: 0.63 | F10: =IFERROR((D10+E10)/2," ") -> 0.595 | G10: =F10-$F$7 -> 0.595 | K10: X | L10: 0 | M10: =K13 -> 552 | P10: 0.1 | Q10: 0.1 | S10: =E10+P10 -> 0.73 | T10: =F10+Q10 -> 0.695
A11: =A10+TIME(,RAND()*1+(1-0),RAND()*10+5) -> 0.0033680556 | B11: =C11*0.07065 -> 9.891 | C11: 140 | D11: 0.89 | E11: 0.88 | F11: =IFERROR((D11+E11)/2," ") -> 0.885 | G11: =F11-$F$7 -> 0.885 | H11: K30=294 MN/㎥ 이상 | J11: 선택층 | K11: Y | L11: 2.5 | M11: 2.5 | P11: 0.1 | Q11: 0.1 | S11: =E11+P11 -> 0.98 | T11: =F11+Q11 -> 0.985
A12: =A11+TIME(,RAND()*1+(1-0),RAND()*10+10) -> 0.0042592593 | B12: =C12*0.07065 -> 12.36375 | C12: 175 | D12: 0.99 | E12: 1.1 | F12: =IFERROR((D12+E12)/2," ") -> 1.045 | G12: =F12-$F$7 -> 1.045 | K12: DATA입력↓ | L12: 3계열 | P12: 0.1 | Q12: 0.1 | S12: =E12+P12 -> 1.2 | T12: =F12+Q12 -> 1.145
A13: =A12+TIME(,RAND()*1+(1-0),RAND()*10+10) -> 0.005150463 | B13: =C13*0.07065 -> 14.8365 | C13: 210 | D13: 1.13 | E13: 1.33 | F13: =IFERROR((D13+E13)/2," ") -> 1.23 | G13: =F13-$F$7 -> 1.23 | H13: K30=294 MN/㎥ 이상 | J13: 보조기층 | K13: 552 | L13: =M10 -> 552 | M13: =L13 -> 552 | P13: 0.1 | Q13: 0.1 | S13: =E13+P13 -> 1.43 | T13: =F13+Q13 -> 1.33
A14: =A13+TIME(,RAND()*1+(1-0),RAND()*10+10) -> 0.0059606481 | B14: =C14*0.07065 -> 17.30925 | C14: 245 | D14: 1.27 | E14: 1.6 | F14: =IFERROR((D14+E14)/2," ") -> 1.435 | G14: =F14-$F$7 -> 1.435 | K14: =K13/2.5 -> 220.8 | L14: 2.5 | M14: 0 | P14: 0.1 | Q14: 0.1 | S14: =E14+P14 -> 1.7 | T14: =F14+Q14 -> 1.535
A15: =A14+TIME(,RAND()*1+(1-0),RAND()*10+10) -> 0.0068518519 | B15: =C15*0.07065 -> 19.782 | C15: 280 | D15: 1.4 | E15: 1.71 | F15: =IFERROR((D15+E15)/2," ") -> 1.555 | G15: =F15-$F$7 -> 1.555 | H15: K30=294 MN/㎥ 이상 | J15: 뒷채움 | K15: =ROUND(K14,1)*1.3 -> 287.04 | N15: 1/100 | P15: 0.1 | Q15: 0.1 | S15: =E15+P15 -> 1.81 | T15: =F15+Q15 -> 1.655
A16: =A15+TIME(,RAND()*1+(1-0),RAND()*10+10) -> 0.007662037 | B16: =C16*0.07065 -> 22.25475 | C16: 315 | D16: 1.51 | E16: 1.83 | F16: =IFERROR((D16+E16)/2," ") -> 1.67 | G16: =F16-$F$7 -> 1.67 | L16: 계산기 | M16: 기준침하량 | N16: 250
A17: =A16+TIME(,RAND()*1+(1-0),RAND()*10+10) -> 0.0085763889 | B17: =C17*0.07065 -> 24.7275 | C17: 350 | D17: 1.64 | E17: 1.96 | F17: =IFERROR((D17+E17)/2," ") -> 1.8 | G17: =F17-$F$7 -> 1.8 | H17: K30=196 MN/㎥ 이상 | J17: 암성토 | M17: 전(1) | N17: 후(2)
A18: =A17+TIME(,RAND()*1+(1-0),RAND()*10+10) -> 0.0094560185 | B18: =C18*0.07065 -> 27.20025 | C18: 385 | D18: 1.74 | E18: 2.14 | F18: =IFERROR((D18+E18)/2," ") -> 1.94 | G18: =F18-$F$7 -> 1.94 | L18: 침하량(y) | M18: 244 | N18: 257
A19: =A18+TIME(,RAND()*1+(1-0),RAND()*10+10) -> 0.010335648 | B19: =C19*0.07065 -> 29.673 | C19: 420 | D19: 1.85 | E19: 2.35 | F19: =IFERROR((D19+E19)/2," ") -> 2.1 | G19: =F19-$F$7 -> 2.1 | H19: DATA 분석 | L19: 하중강도(x) | M19: 840 | N19: 875
A20: =A19+TIME(,RAND()*1+(1-0),RAND()*10+10) -> 0.011157407 | B20: =C20*0.07065 -> 32.14575 | C20: 455 | D20: 1.97 | E20: 2.49 | F20: =IFERROR((D20+E20)/2," ") -> 2.23 | G20: =F20-$F$7 -> 2.23 | L20: 결 과 | M20: =M19+((N16-M18)/((N18-M18)/(N19-M19))) -> 856.15385
A21: =A20+TIME(,RAND()*1+(1-0),RAND()*10+10) -> 0.012048611 | B21: =C21*0.07065 -> 34.6185 | C21: 490 | D21: 2.09 | E21: 2.55 | F21: =IFERROR((D21+E21)/2," ") -> 2.32 | G21: =F21-$F$7 -> 2.32 | H21: ="K30 = "&ROUND(K13,1)&"÷2.5" -> K30 = 552÷2.5 | L21: K30 | M21: =M20/N16*100 -> 342.46154
A22: =A21+TIME(,RAND()*1+(1-0),RAND()*10+10) -> 0.012858796 | B22: =C22*0.07065 -> 37.09125 | C22: 525 | D22: 2.23 | E22: 2.63 | F22: =IFERROR((D22+E22)/2," ") -> 2.43 | G22: =F22-$F$7 -> 2.43
A23: =A22+TIME(,RAND()*1+(1-0),RAND()*10+10) -> 0.013773148 | B23: =C23*0.07065 -> 39.564 | C23: 560 | D23: 2.34 | E23: 2.69 | F23: =IFERROR((D23+E23)/2," ") -> 2.515 | G23: =F23-$F$7 -> 2.515 | H23: =K14 -> 220.8
A24: =A23+TIME(,RAND()*1+(1-0),RAND()*10+10) -> 0.014618056 | B24: =C24*0.07065 -> 42.03675 | C24: 595 | D24: 2.45 | E24: 2.76 | F24: =IFERROR((D24+E24)/2," ") -> 2.605 | G24: =F24-$F$7 -> 2.605
H26: ="K30 = "&ROUND(K14,1)&"×1.3" -> K30 = 220.8×1.3
H28: =K14*1.3 -> 287.04
H32: 시험 결과
H34: =" ∴ "&ROUND(H23,1)&" ＞ 147 MN/㎥ " -> ∴ 220.8 ＞ 147 MN/㎥
H36: 기준에 적합
A38: ■ 비고 - 재하판 안정을 위해 미리 하중 강도 35kN/㎡ 상당의 하중을 가한 후 제거 - 하중 강도가 35kN/㎡씩 되도록 하중을 단계적으로 증가 - 하중에 의한 침하의 진행이 멈추면 하중계와 변위계 눈금 측정 * 침하 진행이 멈추는 경우의 판단 기준 : 1분간의 침하량이 그 하중 강도에 의한 그 단계의 누적 침하량의 1% 이하 일때 - 쌓기의 치수가 300mm 이하이므로 직경 300mm 재하판 사용 - 상부 아스팔트 콘크리트 포장으로 침하량 2.5mm 적용
A43: 시험자 : 윤 정 필 (인) 확인자 : 백 귀 석 (인) 건설사업관리기술인 : 금 동 훈 (인)
A45: 사 진 대 지
A46: 공사명 : 양촌·용정지구 일반산업단지 부지조성공사
A54: 1 | C54: 내 용
C55: 위 치
C56: 일 시
A64: 2 | C64: 내 용
C65: 위 치
C66: 일 시

Sheet 44
A1: 평 판 재 하 시 험 | L1: K30=2.2×K75 K30=1.3×K40
A2: 공 사 명 : | B2: 진천메가폴리스 산업단지 조성사업 | F2: 시험일자 : | G2: =List!B47 -> 46195 | K2: 시험번호
A3: 시험번호 : | B3: =List!A47 -> 44 | F3: 위 치 : | G3: =List!C47 -> 중로(집) 3-16 (No.36 ~ No.50) 노체 19단(57층) - 1회 | K3: 1 | L3: 지반반력계수 환산
A4: 재하조건 | B4: 재하판 지름 : | C4: 300 | D4: 평판면적 : | E4: =30*30/4*3.14 -> 706.5 | F4: 초기하중 : | G4: 35kN/㎡ | H4: KS F 2310
A5: 시간 min - s | B5: 하중 | D5: 변위계의 눈금(mm) | G5: 침하량 (mm) | H5: 적 용 시 방 기 준 (콘크리트포장)
B6: 전하중 (kN) | C6: 재하응력 (kN/㎡) | D6: 왼쪽 | E6: 오른쪽 | F6: 평균
A7: 0 | B7: 0 | C7: 0 | D7: 0 | E7: 0 | F7: =(D7+E7)/2 -> 0 | G7: 0 | H7: K30=147 MN/㎥ 이상 | J7: 노체
A8: =TIME(,RAND()*1+(1-0),RAND()*10+4) -> 0.00076388889 | B8: =C8*0.07065 -> 2.47275 | C8: 35 | D8: 0.18 | E8: 0.29 | F8: =IFERROR((D8+E8)/2," ") -> 0.235 | G8: =F8-F7 -> 0.235 | P8: 0.1 | Q8: 0.1 | S8: =E8+P8 -> 0.39 | T8: =F8+Q8 -> 0.335
A9: =A8+TIME(,RAND()*1+(1-0),RAND()*10+10) -> 0.0016203704 | B9: =C9*0.07065 -> 4.9455 | C9: 70 | D9: 0.39 | E9: 0.4 | F9: =IFERROR((D9+E9)/2," ") -> 0.395 | G9: =F9-$F$7 -> 0.395 | H9: K30=196 MN/㎥ 이상 | J9: 노상 | L9: 2계열 | P9: 0.1 | Q9: 0.1 | S9: =E9+P9 -> 0.5 | T9: =F9+Q9 -> 0.495
A10: =A9+TIME(,RAND()*1+(1-0),RAND()*10+5) -> 0.0024421296 | B10: =C10*0.07065 -> 7.41825 | C10: 105 | D10: 0.5 | E10: 0.61 | F10: =IFERROR((D10+E10)/2," ") -> 0.555 | G10: =F10-$F$7 -> 0.555 | K10: X | L10: 0 | M10: =K13 -> 549 | P10: 0.1 | Q10: 0.1 | S10: =E10+P10 -> 0.71 | T10: =F10+Q10 -> 0.655
A11: =A10+TIME(,RAND()*1+(1-0),RAND()*10+5) -> 0.003287037 | B11: =C11*0.07065 -> 9.891 | C11: 140 | D11: 0.74 | E11: 0.73 | F11: =IFERROR((D11+E11)/2," ") -> 0.735 | G11: =F11-$F$7 -> 0.735 | H11: K30=294 MN/㎥ 이상 | J11: 선택층 | K11: Y | L11: 2.5 | M11: 2.5 | P11: 0.1 | Q11: 0.1 | S11: =E11+P11 -> 0.83 | T11: =F11+Q11 -> 0.835
A12: =A11+TIME(,RAND()*1+(1-0),RAND()*10+10) -> 0.0041319444 | B12: =C12*0.07065 -> 12.36375 | C12: 175 | D12: 0.89 | E12: 0.88 | F12: =IFERROR((D12+E12)/2," ") -> 0.885 | G12: =F12-$F$7 -> 0.885 | K12: DATA입력↓ | L12: 3계열 | P12: 0.1 | Q12: 0.1 | S12: =E12+P12 -> 0.98 | T12: =F12+Q12 -> 0.985
A13: =A12+TIME(,RAND()*1+(1-0),RAND()*10+10) -> 0.0049884259 | B13: =C13*0.07065 -> 14.8365 | C13: 210 | D13: 1.04 | E13: 1.03 | F13: =IFERROR((D13+E13)/2," ") -> 1.035 | G13: =F13-$F$7 -> 1.035 | H13: K30=294 MN/㎥ 이상 | J13: 보조기층 | K13: 549 | L13: =M10 -> 549 | M13: =L13 -> 549 | P13: 0.1 | Q13: 0.1 | S13: =E13+P13 -> 1.13 | T13: =F13+Q13 -> 1.135
A14: =A13+TIME(,RAND()*1+(1-0),RAND()*10+10) -> 0.0059027778 | B14: =C14*0.07065 -> 17.30925 | C14: 245 | D14: 1.22 | E14: 1.33 | F14: =IFERROR((D14+E14)/2," ") -> 1.275 | G14: =F14-$F$7 -> 1.275 | K14: =K13/2.5 -> 219.6 | L14: 2.5 | M14: 0 | P14: 0.1 | Q14: 0.1 | S14: =E14+P14 -> 1.43 | T14: =F14+Q14 -> 1.375
A15: =A14+TIME(,RAND()*1+(1-0),RAND()*10+10) -> 0.0067361111 | B15: =C15*0.07065 -> 19.782 | C15: 280 | D15: 1.34 | E15: 1.49 | F15: =IFERROR((D15+E15)/2," ") -> 1.415 | G15: =F15-$F$7 -> 1.415 | H15: K30=294 MN/㎥ 이상 | J15: 뒷채움 | K15: =ROUND(K14,1)*1.3 -> 285.48 | N15: 1/100 | P15: 0.1 | Q15: 0.1 | S15: =E15+P15 -> 1.59 | T15: =F15+Q15 -> 1.515
A16: =A15+TIME(,RAND()*1+(1-0),RAND()*10+10) -> 0.007650463 | B16: =C16*0.07065 -> 22.25475 | C16: 315 | D16: 1.43 | E16: 1.71 | F16: =IFERROR((D16+E16)/2," ") -> 1.57 | G16: =F16-$F$7 -> 1.57 | L16: 계산기 | M16: 기준침하량 | N16: 250
A17: =A16+TIME(,RAND()*1+(1-0),RAND()*10+10) -> 0.0084953704 | B17: =C17*0.07065 -> 24.7275 | C17: 350 | D17: 1.59 | E17: 1.9 | F17: =IFERROR((D17+E17)/2," ") -> 1.745 | G17: =F17-$F$7 -> 1.745 | H17: K30=196 MN/㎥ 이상 | J17: 암성토 | M17: 전(1) | N17: 후(2)
A18: =A17+TIME(,RAND()*1+(1-0),RAND()*10+10) -> 0.0093865741 | B18: =C18*0.07065 -> 27.20025 | C18: 385 | D18: 1.71 | E18: 2.05 | F18: =IFERROR((D18+E18)/2," ") -> 1.88 | G18: =F18-$F$7 -> 1.88 | L18: 침하량(y) | M18: 244 | N18: 257
A19: =A18+TIME(,RAND()*1+(1-0),RAND()*10+10) -> 0.010219907 | B19: =C19*0.07065 -> 29.673 | C19: 420 | D19: 1.88 | E19: 2.19 | F19: =IFERROR((D19+E19)/2," ") -> 2.035 | G19: =F19-$F$7 -> 2.035 | H19: DATA 분석 | L19: 하중강도(x) | M19: 840 | N19: 875
A20: =A19+TIME(,RAND()*1+(1-0),RAND()*10+10) -> 0.011064815 | B20: =C20*0.07065 -> 32.14575 | C20: 455 | D20: 1.99 | E20: 2.36 | F20: =IFERROR((D20+E20)/2," ") -> 2.175 | G20: =F20-$F$7 -> 2.175 | L20: 결 과 | M20: =M19+((N16-M18)/((N18-M18)/(N19-M19))) -> 856.15385
A21: =A20+TIME(,RAND()*1+(1-0),RAND()*10+10) -> 0.011944444 | B21: =C21*0.07065 -> 34.6185 | C21: 490 | D21: 2.12 | E21: 2.48 | F21: =IFERROR((D21+E21)/2," ") -> 2.3 | G21: =F21-$F$7 -> 2.3 | H21: ="K30 = "&ROUND(K13,1)&"÷2.5" -> K30 = 549÷2.5 | L21: K30 | M21: =M20/N16*100 -> 342.46154
A22: =A21+TIME(,RAND()*1+(1-0),RAND()*10+10) -> 0.012777778 | B22: =C22*0.07065 -> 37.09125 | C22: 525 | D22: 2.26 | E22: 2.59 | F22: =IFERROR((D22+E22)/2," ") -> 2.425 | G22: =F22-$F$7 -> 2.425
A23: =A22+TIME(,RAND()*1+(1-0),RAND()*10+10) -> 0.013587963 | B23: =C23*0.07065 -> 39.564 | C23: 560 | D23: 2.39 | E23: 2.63 | F23: =IFERROR((D23+E23)/2," ") -> 2.51 | G23: =F23-$F$7 -> 2.51 | H23: =K14 -> 219.6
A24: =A23+TIME(,RAND()*1+(1-0),RAND()*10+10) -> 0.014479167 | B24: =C24*0.07065 -> 42.03675 | C24: =C23+35 -> 595 | D24: 2.46 | E24: 2.7 | F24: =IFERROR((D24+E24)/2," ") -> 2.58 | G24: =F24-$F$7 -> 2.58
H26: ="K30 = "&ROUND(K14,1)&"×1.3" -> K30 = 219.6×1.3
H28: =K14*1.3 -> 285.48
H32: 시험 결과
H34: =" ∴ "&ROUND(H23,1)&" ＞ 147 MN/㎥ " -> ∴ 219.6 ＞ 147 MN/㎥
H36: 기준에 적합
A38: ■ 비고 - 재하판 안정을 위해 미리 하중 강도 35kN/㎡ 상당의 하중을 가한 후 제거 - 하중 강도가 35kN/㎡씩 되도록 하중을 단계적으로 증가 - 하중에 의한 침하의 진행이 멈추면 하중계와 변위계 눈금 측정 * 침하 진행이 멈추는 경우의 판단 기준 : 1분간의 침하량이 그 하중 강도에 의한 그 단계의 누적 침하량의 1% 이하 일때 - 쌓기의 치수가 300mm 이하이므로 직경 300mm 재하판 사용 - 상부 아스팔트 콘크리트 포장으로 침하량 2.5mm 적용
A43: 시험자 : 윤 정 필 (인) 확인자 : 백 귀 석 (인) 건설사업관리기술인 : 금 동 훈 (인)
A45: 사 진 대 지
A46: 공사명 : 양촌·용정지구 일반산업단지 부지조성공사
A54: 1 | C54: 내 용
C55: 위 치
C56: 일 시
A64: 2 | C64: 내 용
C65: 위 치
C66: 일 시

Sheet 43
A1: 평 판 재 하 시 험 | L1: K30=2.2×K75 K30=1.3×K40
A2: 공 사 명 : | B2: 진천메가폴리스 산업단지 조성사업 | F2: 시험일자 : | G2: =List!B46 -> 46189 | K2: 시험번호
A3: 시험번호 : | B3: =List!A46 -> 43 | F3: 위 치 : | G3: =List!C46 -> 중로(집) 3-16 (No.36 ~ No.50) 노체 18단(54층) - 2회 | K3: 1 | L3: 지반반력계수 환산
A4: 재하조건 | B4: 재하판 지름 : | C4: 300 | D4: 평판면적 : | E4: =30*30/4*3.14 -> 706.5 | F4: 초기하중 : | G4: 35kN/㎡ | H4: KS F 2310
A5: 시간 min - s | B5: 하중 | D5: 변위계의 눈금(mm) | G5: 침하량 (mm) | H5: 적 용 시 방 기 준 (콘크리트포장)
B6: 전하중 (kN) | C6: 재하응력 (kN/㎡) | D6: 왼쪽 | E6: 오른쪽 | F6: 평균
A7: 0 | B7: 0 | C7: 0 | D7: 0 | E7: 0 | F7: =(D7+E7)/2 -> 0 | G7: 0 | H7: K30=147 MN/㎥ 이상 | J7: 노체
