Workbook
Name _bar10: #REF!
Name _bar13: #REF!
Name _bar16: #REF!
Name _bar19: #REF!
Name _bar22: #REF!
Name _bar25: #REF!
Name _bar29: #REF!
Name _bar32: #REF!
Name _GHH1: #REF!
Name _GHH2: #REF!
Name _HSH1: #REF!
Name _HSH2: #REF!
Name _JEA1: #REF!
Name _JEA2: #REF!
Name _JH10: [1]현황산출서!#REF!
Name _JH10: [1]현황산출서!#REF!
Name _JH10: [1]현황산출서!#REF!
Name _JH10: [1]현황산출서!#REF!
Name _JH11: [1]현황산출서!#REF!
Name _JH11: [1]현황산출서!#REF!
Name _JH11: [1]현황산출서!#REF!
Name _JH11: [1]현황산출서!#REF!
Name _JH12: [1]현황산출서!#REF!
Name _JH12: [1]현황산출서!#REF!
Name _JH12: [1]현황산출서!#REF!
Name _JH12: [1]현황산출서!#REF!
Name _JH13: [1]현황산출서!#REF!
Name _JH13: [1]현황산출서!#REF!
Name _JH13: [1]현황산출서!#REF!
Name _JH13: [1]현황산출서!#REF!
Name _JH14: [1]현황산출서!#REF!
Name _JH14: [1]현황산출서!#REF!
Name _JH14: [1]현황산출서!#REF!
Name _JH14: [1]현황산출서!#REF!
Name _JH15: [1]현황산출서!#REF!
Name _JH15: [1]현황산출서!#REF!
Name _JH15: [1]현황산출서!#REF!
Name _JH15: [1]현황산출서!#REF!
Name _JH16: [1]현황산출서!#REF!
Name _JH16: [1]현황산출서!#REF!
Name _JH16: [1]현황산출서!#REF!
Name _JH16: [1]현황산출서!#REF!
Name _JH17: [1]현황산출서!#REF!
Name _JH17: [1]현황산출서!#REF!
Name _JH17: [1]현황산출서!#REF!
Name _JH17: [1]현황산출서!#REF!
Name _JH18: [1]현황산출서!#REF!
Name _JH18: [1]현황산출서!#REF!
Name _JH18: [1]현황산출서!#REF!
Name _JH18: [1]현황산출서!#REF!
Name _JH19: [1]현황산출서!#REF!
Name _JH19: [1]현황산출서!#REF!
Name _JH19: [1]현황산출서!#REF!
Name _JH19: [1]현황산출서!#REF!
Name _JH20: [1]현황산출서!#REF!
Name _JH20: [1]현황산출서!#REF!
Name _JH20: [1]현황산출서!#REF!
Name _JH20: [1]현황산출서!#REF!
Name _jh8: [1]현황산출서!#REF!
Name _jh8: [1]현황산출서!#REF!

Sheet 원가계산서(총괄)
A2: 원 가 계 산 서 (총괄)
A3: [공사명 : 진천 메가폴리스 산업단지 조성사업]
A5: 구 분 | F5: 토 목 | G5: 전 기 | H5: 합 계 | I5: 비 고 | L5: 토목공사
A6: 순 공 사 원 가 | B6: 재 료 비 | D6: 직 접 재 료 비 | F6: ='원가계산서(토목공사)'!F6 -> 66523722128 | G6: ='원가계산서(전기공사)'!F6 -> 1972482406 | H6: =F6+G6 -> 68496204534
D7: 간 접 재 료 비 | H7: =F7+G7 -> 0
D8: 소 계 | F8: =SUM(F6:F7) -> 66523722128 | G8: =SUM(G6:G7) -> 1972482406 | H8: =F8+G8 -> 68496204534
B9: 노 무 비 | D9: 직 접 노 무 비 | F9: ='원가계산서(토목공사)'!F9 -> 55865798826 | G9: ='원가계산서(전기공사)'!F9 -> 1037484768 | H9: =F9+G9 -> 56903283594
D10: 간 접 노 무 비 | F10: ='원가계산서(토목공사)'!F10 -> 7486017042 | G10: ='원가계산서(전기공사)'!F10 -> 137985474 | H10: =F10+G10 -> 7624002516
D11: 소 계 | F11: =SUM(F9:F10) -> 63351815868 | G11: =SUM(G9:G10) -> 1175470242 | H11: =F11+G11 -> 64527286110
B12: 경 비 | D12: 산 출 경 비 | F12: ='원가계산서(토목공사)'!F12 -> 29621556618 | G12: ='원가계산서(전기공사)'!F12 -> 22109916 | H12: =F12+G12 -> 29643666534
D13: 산 재 보 험 료 | F13: ='원가계산서(토목공사)'!F13 -> 2255324644 | G13: ='원가계산서(전기공사)'!F13 -> 41846740 | H13: =F13+G13 -> 2297171384
D14: 고 용 보 험 료 | F14: ='원가계산서(토목공사)'!F14 -> 994623509 | G14: ='원가계산서(전기공사)'!F14 -> 11872249 | H14: =F14+G14 -> 1006495758
D15: 건 강 보 험 료 | F15: ='원가계산서(토목공사)'!F15 -> 2377966250 | G15: ='원가계산서(전기공사)'!F15 -> 44336163 | H15: =F15+G15 -> 2422302413
D16: 노인장기요양보험료 | F16: ='원가계산서(토목공사)'!F16 -> 307946629 | G16: ='원가계산서(전기공사)'!F18 -> 5741533 | H16: =F16+G16 -> 313688162
D17: 연 금 보 험 료 | F17: ='원가계산서(토목공사)'!F17 -> 3018574930 | G17: ='원가계산서(전기공사)'!F16 -> 56280038 | H17: =F17+G17 -> 3074854968
D18: 퇴 직 공 제 부 금 비 | F18: ='원가계산서(토목공사)'!F18 -> 1542827186 | G18: ='원가계산서(전기공사)'!F17 -> 28765353 | H18: =F18+G18 -> 1571592539
D19: 건설기계대여대금지급보증서 | F19: ='원가계산서(토목공사)'!F19 -> 608044310 | H19: =F19+G19 -> 608044310
D20: 산업안전보건관리비 | F20: ='원가계산서(토목공사)'!F20 -> 2027901531 | G20: ='원가계산서(전기공사)'!F19 -> 86334499 | H20: =F20+G20 -> 2114236030
D21: 환 경 보 전 비 | F21: ='원가계산서(토목공사)'!F21 -> 912066465 | H21: =F21+G21 -> 912066465
D22: 건설하도급대금지급보증서발급수수료 | F22: ='원가계산서(토목공사)'!F22 -> 107927865 | H22: =F22+G22 -> 107927865
D23: 기 타 경 비 | F23: ='원가계산서(토목공사)'!F23 -> 8961412121 | G23: ='원가계산서(전기공사)'!F21 -> 223504638 | H23: =F23+G23 -> 9184916759
D24: 소 계 | F24: =SUM(F12:F23) -> 52736172058 | G24: =SUM(G12:G23) -> 520791129 | H24: =F24+G24 -> 53256963187 | K24: 직접공사비 | L24: =SUM(F6,F9,F12) -> 152011077572
A25: 합 계 | F25: =SUM(F8+F11+F24) -> 182611710054 | G25: =SUM(G8+G11+G24) -> 3668743777 | H25: =F25+G25 -> 186280453831 | K25: 간접비 | L25: =SUM(F10,F13:F23,F26,F28) -> 50024007857
B26: 일 반 관 리 비 | F26: ='원가계산서(토목공사)'!F26 -> 8217526952 | G26: ='원가계산서(전기공사)'!F26 -> 201780907 | H26: =F26+G26 -> 8419307859
B27: 피 해 방 지 대 책 비 용 | F27: ='원가계산서(토목공사)'!F27 -> 209912160 | H27: =F27+G27 -> 209912160 | K27: 간접비율 | L27: =L25/L24 -> 0.32908133 | M27: (부가세 별도)
B28: 이 윤 | F28: ='원가계산서(토목공사)'!F28 -> 11205848423 | G28: ='원가계산서(전기공사)'!F27 -> 284651680 | H28: =F28+G28 -> 11490500103
B29: G I S 측 량 성 과 비 | F29: ='원가계산서(토목공사)'!F29 -> 453609000 | H29: =F29+G29 -> 453609000
B30: 시 공 측 량 비 | F30: ='원가계산서(토목공사)'!F30 -> 142023000 | H30: =F30+G30 -> 142023000
B31: 폐 기 물 처 리 용 역 | F31: ='원가계산서(토목공사)'!F31 -> 1113009593 | H31: =F31+G31 -> 1113009593
B32: 계 측 관 리 | F32: ='원가계산서(토목공사)'!F32 -> 86639000 | H32: =F32+G32 -> 86639000
B33: 공 급 가 액 | F33: =INT(SUM(F25,F26,F27,F28,F29,F30,F31,F32)) -> 204040278182 | G33: =INT(SUM(G25,G26,G27,G28,G29,G30,G31,G32)) -> 4155176364 | H33: =F33+G33 -> 208195454546
B34: 부 가 가 치 세 | F34: =TRUNC(F33*0.1,0) -> 20404027818 | G34: =TRUNC(G33*0.1,0) -> 415517636 | H34: =F34+G34 -> 20819545454
B35: 도 급 공 사 비 | F35: =SUM(F33:F34) -> 224444306000 | G35: =SUM(G33:G34) -> 4570694000 | H35: =F35+G35 -> 229015000000 | K35: (계약금액)
B36: 수 탁 비 | F36: =INT(I36/1000)*1000 -> 0 | G36: ='원가계산서(전기공사)'!F34 -> 42000000 | H36: =F36+G36 -> 42000000
B37: 총 공 사 비 | F37: =F35+F36 -> 224444306000 | G37: =G35+G36 -> 4612694000 | H37: =F37+G37 -> 229057000000
F40: =F39*0.86 -> 0

Sheet 공사비총괄표
A1: 공 사 비 총 괄 표
A2: 공사명 : 진천 메가폴리스 산업단지 조성사업
A3: 공 종 명 | B3: 규 격 | C3: 수량 | D3: 단위 | E3: 노 무 비 | G3: 재 료 비 | I3: 경 비 | K3: 합 계 | M3: 비 고
E4: 단 가 | F4: 금 액 | G4: 단 가 | H4: 금 액 | I4: 단 가 | J4: 금 액 | K4: 단 가 | L4: 금 액
A5: 진천 메가폴리스 일반산업단지 조성사업 | C5: 1 | D5: 식 | F5: =TRUNC(F6+F7+F10+F11+F12+F13+F14+F15+F16+F17+F18+F19+F20+F21+F22+F23+F24+F25+F26+F27+F28+F29+F310+F31+F33) -> 64527286110 | H5: =TRUNC(H6+H7+H10+H11+H12+H13+H14+H15+H16+H17+H18+H19+H20+H21+H22+H23+H24+H25+H26+H27+H28+H29+H310+H31+H33) -> 68496204534 | J5: =TRUNC(J6+J7+J10+J11+J12+J13+J14+J15+J16+J17+J18+J19+J20+J21+J22+J23+J24+J25+J26+J27+J28+J29+J310+J31+J33) -> 96033509356 | L5: =H5+F5+J5 -> 229057000000
A6: 1.토목공사 | C6: 1 | D6: 식 | E6: ='원가계산서(토목공사)'!F9 -> 55865798826 | F6: =TRUNC(E6*$C6,0) -> 55865798826 | G6: ='원가계산서(토목공사)'!F6 -> 66523722128 | H6: =TRUNC(G6*$C6,0) -> 66523722128 | I6: ='원가계산서(토목공사)'!F12 -> 29621556618 | J6: =TRUNC(I6*$C6,0) -> 29621556618 | K6: =G6+E6+I6 -> 152011077572 | L6: =H6+F6+J6 -> 152011077572
A7: 2.전기공사 | C7: 1 | D7: 식 | E7: ='원가계산서(총괄)'!G9 -> 1037484768 | F7: =TRUNC(E7*$C7,0) -> 1037484768 | G7: ='원가계산서(총괄)'!G6 -> 1972482406 | H7: =TRUNC(G7*$C7,0) -> 1972482406 | I7: ='원가계산서(총괄)'!G12 -> 22109916 | J7: =TRUNC(I7*$C7,0) -> 22109916 | K7: =G7+E7+I7 -> 3032077090 | L7: =H7+F7+J7 -> 3032077090
F8: 0 | H8: 0 | J8: 0 | K8: =G8+E8+I8 -> 0 | L8: =H8+F8+J8 -> 0
A9: 직 접 공 사 비 | C9: 1 | D9: 식 | F9: =F6+F7 -> 56903283594 | H9: =H6+H7 -> 68496204534 | J9: =J6+J7 -> 29643666534 | K9: =G9+E9+I9 -> 0 | L9: =H9+F9+J9 -> 155043154662
A10: 간 접 재 료 비 | C10: 1 | D10: 식 | F10: 0 | H10: =TRUNC((0*0/100),0) -> 0 | J10: 0 | K10: =G10+E10+I10 -> 0 | L10: =H10+F10+J10 -> 0
A11: 간 접 노 무 비 | C11: 1 | D11: 식 | F11: ='원가계산서(총괄)'!H10 -> 7624002516 | H11: 0 | J11: 0 | K11: =G11+E11+I11 -> 0 | L11: =H11+F11+J11 -> 7624002516
A12: 산 재 보 험 료 | C12: 1 | D12: 식 | H12: 0 | J12: ='원가계산서(총괄)'!H13 -> 2297171384 | K12: =G12+E12+I12 -> 0 | L12: =H12+F12+J12 -> 2297171384
A13: 고 용 보 험 료 | C13: 1 | D13: 식 | H13: 0 | J13: ='원가계산서(총괄)'!H14 -> 1006495758 | K13: =G13+E13+I13 -> 0 | L13: =H13+F13+J13 -> 1006495758
A14: 건 강 보 험 료 | C14: 1 | D14: 식 | H14: 0 | J14: ='원가계산서(총괄)'!H15 -> 2422302413 | K14: =G14+E14+I14 -> 0 | L14: =H14+F14+J14 -> 2422302413
A15: 노인장기요양보험료 | C15: 1 | D15: 식 | H15: 0 | J15: ='원가계산서(총괄)'!H16 -> 313688162 | K15: =G15+E15+I15 -> 0 | L15: =H15+F15+J15 -> 313688162
A16: 연 금 보 험 료 | C16: 1 | D16: 식 | H16: 0 | J16: ='원가계산서(총괄)'!H17 -> 3074854968 | K16: =G16+E16+I16 -> 0 | L16: =H16+F16+J16 -> 3074854968
A17: 퇴 직 공 제 부 금 | C17: 1 | D17: 식 | H17: 0 | J17: ='원가계산서(총괄)'!H18 -> 1571592539 | K17: =G17+E17+I17 -> 0 | L17: =H17+F17+J17 -> 1571592539
A18: 건설기계대여대금지급보증서 | C18: 1 | D18: 식 | H18: 0 | J18: ='원가계산서(총괄)'!H19 -> 608044310 | K18: =G18+E18+I18 -> 0 | L18: =H18+F18+J18 -> 608044310
A19: 산업안전보건관리비 | C19: 1 | D19: 식 | H19: 0 | J19: ='원가계산서(총괄)'!H20 -> 2114236030 | K19: =G19+E19+I19 -> 0 | L19: =H19+F19+J19 -> 2114236030
A20: 환 경 보 전 비 | C20: 1 | D20: 식 | H20: 0 | J20: ='원가계산서(총괄)'!H21 -> 912066465 | K20: =G20+E20+I20 -> 0 | L20: =H20+F20+J20 -> 912066465
A21: 건설하도급대금지급보증서발급수수료 | C21: 1 | D21: 식 | H21: 0 | J21: ='원가계산서(총괄)'!H22 -> 107927865 | K21: =G21+E21+I21 -> 0 | L21: =H21+F21+J21 -> 107927865
A22: 기 타 경 비 | C22: 1 | D22: 식 | H22: 0 | J22: ='원가계산서(총괄)'!H23 -> 9184916759 | K22: =G22+E22+I22 -> 0 | L22: =H22+F22+J22 -> 9184916759
A23: 일 반 관 리 비 | C23: 1 | D23: 식 | H23: 0 | J23: ='원가계산서(총괄)'!H26 -> 8419307859 | K23: =G23+E23+I23 -> 0 | L23: =H23+F23+J23 -> 8419307859
A24: 피해방지대책비용 | C24: 1 | D24: 식 | H24: 0 | J24: ='원가계산서(총괄)'!H27 -> 209912160 | K24: =G24+E24+I24 -> 0 | L24: =H24+F24+J24 -> 209912160
A25: 이 윤 | C25: 1 | D25: 식 | H25: 0 | J25: ='원가계산서(총괄)'!H28 -> 11490500103 | K25: =G25+E25+I25 -> 0 | L25: =H25+F25+J25 -> 11490500103
A26: GIS측량성과비 | C26: 1 | D26: 식 | E26: 0 | G26: 0 | J26: ='원가계산서(총괄)'!H29 -> 453609000 | K26: =G26+E26+I26 -> 0 | L26: =H26+F26+J26 -> 453609000
A27: 시공측량비 | C27: 21 | D27: km | G27: 0 | J27: ='원가계산서(총괄)'!H30 -> 142023000 | K27: =G27+E27+I27 -> 0 | L27: =H27+F27+J27 -> 142023000
A28: 폐기물처리용역 | C28: 1 | D28: 식 | H28: =TRUNC(G28*C28,0) -> 0 | J28: ='원가계산서(총괄)'!H31 -> 1113009593 | K28: =G28+E28+I28 -> 0 | L28: =H28+F28+J28 -> 1113009593
A29: 계측관리 | C29: 1 | D29: 식 | G29: 0 | J29: ='원가계산서(총괄)'!H32 -> 86639000 | K29: =G29+E29+I29 -> 0 | L29: =H29+F29+J29 -> 86639000
A30: 공 급 가 액 | C30: 1 | D30: 식 | H30: 0 | J30: =TRUNC((H9+J9+F9+F11+J12+J13+J14+J15+J16+J17+J18+J19+J20+J21+J22+J23+J24+J25+J26+J27+H28+J28+J29),0) -> 208195454546 | K30: =G30+E30+I30 -> 0 | L30: =H30+F30+J30 -> 208195454546
A31: 부 가 가 치 세 | C31: 1 | D31: 식 | H31: 0 | J31: ='원가계산서(총괄)'!H34 -> 20819545454 | K31: =G31+E31+I31 -> 0 | L31: =H31+F31+J31 -> 20819545454
A32: 도 급 액 | C32: 1 | D32: 식 | H32: 0 | J32: =J30+J31 -> 229015000000 | K32: =G32+E32+I32 -> 0 | L32: =H32+F32+J32 -> 229015000000
A33: 한 전 수 탁 비 | C33: 1 | D33: 식 | H33: 0 | J33: ='원가계산서(총괄)'!H36 -> 42000000 | K33: =G33+E33+I33 -> 0 | L33: =H33+F33+J33 -> 42000000
A34: 총 공 사 비 | C34: 1 | D34: 식 | H34: 0 | J34: =J32+J33 -> 229057000000 | K34: =G34+E34+I34 -> 0 | L34: =H34+F34+J34 -> 229057000000

Sheet 원가계산서(토목공사)
A2: 원 가 계 산 서 (토목)
A3: [공사명 : 진천 메가폴리스 산업단지 조성사업]
A5: 구 분 | F5: 도 급 금 액 | G5: 비 고
A6: 순 공 사 원 가 | B6: 재 료 비 | D6: 직 접 재 료 비 | F6: ='내역서(토목공사)'!H18 -> 66523722128
D7: 간 접 재 료 비
D8: 소 계 | F8: =SUM(F6:F7) -> 66523722128
B9: 노 무 비 | D9: 직 접 노 무 비 | F9: ='내역서(토목공사)'!F18 -> 55865798826
D10: 간 접 노 무 비 | F10: =TRUNC(($F$9)*G10%) -> 7486017042 | G10: 13.4
D11: 소 계 | F11: =SUM(F9:F10) -> 63351815868
B12: 경 비 | D12: 산 출 경 비 | F12: ='내역서(토목공사)'!J18 -> 29621556618
D13: 산 재 보 험 료 | F13: =TRUNC(($F$9+$F$10)*G13%) -> 2255324644 | G13: 3.56
D14: 고 용 보 험 료 | F14: =TRUNC(($F$9+$F$10)*G14%) -> 994623509 | G14: 1.57 | I14: 설계금액
D15: 건 강 보 험 료 | F15: =TRUNC(($F$9)*G15%)*0+I15 -> 2377966250 | G15: 3.545 | I15: 2377966250
D16: 노인장기요양보험료 | F16: =TRUNC(($F$15)*G16%)*0+I16 -> 307946629 | G16: 12.95 | I16: 307946629
D17: 연 금 보 험 료 | F17: =TRUNC(($F$9)*G17%)*0+I17 -> 3018574930 | G17: 4.5 | I17: 3018574930
D18: 퇴 직 공 제 부 금 비 | F18: =TRUNC(($F$9)*G18%)*0+I18 -> 1542827186 | G18: 2.3 | I18: 1542827186
D19: 건설기계대여대금지급보증서 | F19: =TRUNC(($F$6+$F$9+$F$12)*G19%) -> 608044310 | G19: 0.4
D20: 산업안전보건관리비 | F20: =TRUNC(($F$6+$F$9)*G20%)*0+I20 -> 2027901531 | G20: 1.38 | I20: 2027901531
D21: 환 경 보 전 비 | F21: =TRUNC(($F$6+$F$9+$F$12)*G21%) -> 912066465 | G21: 0.6
D22: 건설하도급대금지급보증서발급수수료 | F22: =TRUNC(($F$6+$F$9+$F$12)*G22%) -> 107927865 | G22: 0.071
D23: 기 타 경 비 | F23: =TRUNC(($F$6+$F$11)*G23%) -> 8961412121 | G23: 6.9
D24: 소 계 | F24: =SUM(F12:F23) -> 52736172058
A25: 합 계 | F25: =SUM(F8+F11+F24) -> 182611710054
B26: 일 반 관 리 비 | F26: =TRUNC(($F$25)*G26%) -> 8217526952 | G26: 4.5
B27: 피 해 방 지 대 책 비 용 | F27: =TRUNC(($F$25+$F$26)*G27%) -> 209912160 | G27: 0.11
B28: 이 윤 | F28: =TRUNC(($F$11+$F$24+$F$26+$F$27)*G28%)-INT(594011/1.1) -> 11205848423 | G28: 9
B29: G I S 측 량 성 과 비 | F29: ='내역서(토목공사)'!L35 -> 453609000
B30: 시 공 측 량 비 | F30: ='내역서(토목공사)'!L36 -> 142023000
B31: 폐 기 물 처 리 용 역 | F31: ='내역서(토목공사)'!L37 -> 1113009593
B32: 계 측 관 리 | F32: ='내역서(토목공사)'!L38 -> 86639000 | G32: 사면
B33: 공 급 가 액 | F33: =INT(SUM(F25,F26,F27,F28,F29,F30,F31,F32)) -> 204040278182
B34: 부 가 가 치 세 | F34: =TRUNC(F33*0.1,0) -> 20404027818
B35: 도 급 공 사 비 | F35: =SUM(F33:F34) -> 224444306000

Sheet 내역서(토목공사)
A1: 도 급 내 역 서
A2: 공사명 : 진천 메가폴리스 산업단지 조성사업
A3: 공 종 명 | B3: 규 격 | C3: 수량 | D3: 단위 | E3: 노 무 비 | G3: 재 료 비 | I3: 경 비 | K3: 합 계 | M3: 비 고
E4: 단 가 | F4: 금 액 | G4: 단 가 | H4: 금 액 | I4: 단 가 | J4: 금 액 | K4: 단 가 | L4: 금 액
A5: 진천 메가폴리스 일반산업단지 조성사업 | C5: 1 | D5: 식 | F5: =TRUNC(F6+F7+F8+F9+F10+F11+F12+F13+F14+F15+F16+F19+F20+F21+F22+F23+F24+F25+F26+F27+F28+F29+F30+F31+F32+F33+F34+F35+F36+F37+F38+F40,0) -> 63351815868 | H5: =TRUNC(H6+H7+H8+H9+H10+H11+H12+H13+H14+H15+H16+H19+H20+H21+H22+H23+H24+H25+H26+H27+H28+H29+H30+H31+H32+H33+H34+H35+H36+H37+H38+H40,0) -> 66361975118 | J5: =TRUNC(J6+J7+J8+J9+J10+J11+J12+J13+J14+J15+J16+J19+J20+J21+J22+J23+J24+J25+J26+J27+J28+J29+J30+J31+J32+J33+J34+J35+J36+J37+J38+J40,0) -> 94730515014 | L5: =H5+F5+J5 -> 224444306000
A6: 1.토 공 | C6: 1 | D6: 식 | E6: =F68 -> 45679031635 | F6: =TRUNC(E6*$C6,0) -> 45679031635 | G6: =H68 -> 34503742445 | H6: =TRUNC(G6*$C6,0) -> 34503742445 | I6: =J68 -> 24142306805 | J6: =TRUNC(I6*$C6,0) -> 24142306805 | K6: =G6+E6+I6 -> 104325080885 | L6: =H6+F6+J6 -> 104325080885
A7: 2.우수공 | C7: 1 | D7: 식 | E7: =F192 -> 3010933998 | F7: =TRUNC(E7*$C7,0) -> 3010933998 | G7: =H192 -> 17125536464 | H7: =TRUNC(G7*$C7,0) -> 17125536464 | I7: =J192 -> 1303483758 | J7: =TRUNC(I7*$C7,0) -> 1303483758 | K7: =G7+E7+I7 -> 21439954220 | L7: =H7+F7+J7 -> 21439954220
A8: 3.오수공 | C8: 1 | D8: 식 | E8: =F529 -> 485844891 | F8: =TRUNC(E8*$C8,0) -> 485844891 | G8: =H529 -> 1149654085 | H8: =TRUNC(G8*$C8,0) -> 1149654085 | I8: =J529 -> 141779721 | J8: =TRUNC(I8*$C8,0) -> 141779721 | K8: =G8+E8+I8 -> 1777278697 | L8: =H8+F8+J8 -> 1777278697
A9: 4.상수공 | C9: 1 | D9: 식 | E9: =F659 -> 892938847 | F9: =TRUNC(E9*$C9,0) -> 892938847 | G9: =H659 -> 2061404807 | H9: =TRUNC(G9*$C9,0) -> 2061404807 | I9: =J659 -> 51455768 | J9: =TRUNC(I9*$C9,0) -> 51455768 | K9: =G9+E9+I9 -> 3005799422 | L9: =H9+F9+J9 -> 3005799422
A10: 5.포장공 | C10: 1 | D10: 식 | E10: =F1091 -> 1811681837 | F10: =TRUNC(E10*$C10,0) -> 1811681837 | G10: =H1091 -> 7851898505 | H10: =TRUNC(G10*$C10,0) -> 7851898505 | I10: =J1091 -> 220097629 | J10: =TRUNC(I10*$C10,0) -> 220097629 | K10: =G10+E10+I10 -> 9883677971 | L10: =H10+F10+J10 -> 9883677971
A11: 6.조경공 | C11: 1 | D11: 식 | E11: =F1240 -> 2569518308 | F11: =TRUNC(E11*$C11,0) -> 2569518308 | G11: =H1240 -> 1308807381 | H11: =TRUNC(G11*$C11,0) -> 1308807381 | I11: =J1240 -> 538865817 | J11: =TRUNC(I11*$C11,0) -> 538865817 | K11: =G11+E11+I11 -> 4417191506 | L11: =H11+F11+J11 -> 4417191506
A12: 8.구조물공 | C12: 1 | D12: 식 | E12: =F1490 -> 694353421 | F12: =TRUNC(E12*$C12,0) -> 694353421 | G12: =H1490 -> 631445266 | H12: =TRUNC(G12*$C12,0) -> 631445266 | I12: =J1490 -> 62635909 | J12: =TRUNC(I12*$C12,0) -> 62635909 | K12: =G12+E12+I12 -> 1388434596 | L12: =H12+F12+J12 -> 1388434596
A13: 9.농수로공 | C13: 1 | D13: 식 | E13: =F1552 -> 12982062 | F13: =TRUNC(E13*$C13,0) -> 12982062 | G13: =H1552 -> 41363394 | H13: =TRUNC(G13*$C13,0) -> 41363394 | I13: =J1552 -> 1601760 | J13: =TRUNC(I13*$C13,0) -> 1601760 | K13: =G13+E13+I13 -> 55947216 | L13: =H13+F13+J13 -> 55947216
A14: 10.하천공 | C14: 1 | D14: 식 | E14: =F1580 -> 491964880 | F14: =TRUNC(E14*$C14,0) -> 491964880 | G14: =H1580 -> 769593823 | H14: =TRUNC(G14*$C14,0) -> 769593823 | I14: =J1580 -> 86738218 | J14: =TRUNC(I14*$C14,0) -> 86738218 | K14: =G14+E14+I14 -> 1348296921 | L14: =H14+F14+J14 -> 1348296921
A15: 11.저류지공 | C15: 1 | D15: 식 | E15: =F1653 -> 127999030 | F15: =TRUNC(E15*$C15,0) -> 127999030 | G15: =H1653 -> 403186048 | H15: =TRUNC(G15*$C15,0) -> 403186048 | I15: =J1653 -> 31570040 | J15: =TRUNC(I15*$C15,0) -> 31570040 | K15: =G15+E15+I15 -> 562755118 | L15: =H15+F15+J15 -> 562755118
A16: 12.부대공 | C16: 1 | D16: 식 | E16: =F1695 -> 88549917 | F16: =TRUNC(E16*$C16,0) -> 88549917 | G16: =H1695 -> 677089910 | H16: =TRUNC(G16*$C16,0) -> 677089910 | I16: =J1695 -> 3041021193 | J16: =TRUNC(I16*$C16,0) -> 3041021193 | K16: =G16+E16+I16 -> 3806661020 | L16: =H16+F16+J16 -> 3806661020
F17: 0 | H17: 0 | J17: 0 | K17: =G17+E17+I17 -> 0 | L17: =H17+F17+J17 -> 0
A18: 직 접 공 사 비 | C18: 1 | D18: 식 | F18: =TRUNC((F6+F7+F8+F9+F10+F11+F12+F13+F14+F15+F16),0) -> 55865798826 | H18: =TRUNC((H6+H7+H8+H9+H10+H11+H12+H13+H14+H15+H16),0) -> 66523722128 | J18: =TRUNC((J6+J7+J8+J9+J10+J11+J12+J13+J14+J15+J16),0) -> 29621556618 | K18: =G18+E18+I18 -> 0 | L18: =H18+F18+J18 -> 152011077572
A19: 간 접 재 료 비 | C19: 1 | D19: 식 | F19: 0 | H19: =TRUNC((0*0/100),0) -> 0 | J19: 0 | K19: =G19+E19+I19 -> 0 | L19: =H19+F19+J19 -> 0
A20: 간 접 노 무 비 | B20: 직접노무비의 13.4% | C20: 1 | D20: 식 | F20: =TRUNC((F18*13.4/100),0) -> 7486017042 | H20: 0 | J20: 0 | K20: =G20+E20+I20 -> 0 | L20: =H20+F20+J20 -> 7486017042
A21: 산 재 보 험 료 | B21: 노무비의 3.56% | C21: 1 | D21: 식 | F21: 0 | H21: 0 | J21: =TRUNC(((F18+F20)*3.56/100),0) -> 2255324644 | K21: =G21+E21+I21 -> 0 | L21: =H21+F21+J21 -> 2255324644
A22: 고 용 보 험 료 | B22: 노무비의 1.57% | C22: 1 | D22: 식 | F22: 0 | H22: 0 | J22: =TRUNC(((F18+F20)*1.57/100),0) -> 994623509 | K22: =G22+E22+I22 -> 0 | L22: =H22+F22+J22 -> 994623509 | O22: 설계금액
A23: 건 강 보 험 료 | B23: 직접노무비의 3.545% | C23: 1 | D23: 식 | F23: 0 | H23: 0 | J23: =TRUNC((F18*3.545/100),0)*0+$O$23 -> 2377966250 | K23: =G23+E23+I23 -> 0 | L23: =H23+F23+J23 -> 2377966250 | O23: 2377966250
A24: 노인장기요양보험료 | B24: 건강보험료의 12.95% | C24: 1 | D24: 식 | F24: 0 | H24: 0 | J24: =TRUNC((J23*12.95/100),0)*0+$O$24 -> 307946629 | K24: =G24+E24+I24 -> 0 | L24: =H24+F24+J24 -> 307946629 | O24: 307946629
A25: 연 금 보 험 료 | B25: 직접노무비의 4.5% | C25: 1 | D25: 식 | F25: 0 | H25: 0 | J25: =TRUNC((F18*4.5/100),0)*0+$O$25 -> 3018574930 | K25: =G25+E25+I25 -> 0 | L25: =H25+F25+J25 -> 3018574930 | O25: 3018574930
A26: 퇴 직 공 제 부 금 | B26: 직접노무비의 2.3% | C26: 1 | D26: 식 | F26: 0 | H26: 0 | J26: =TRUNC((F18*2.3/100),0)*0+$O$26 -> 1542827186 | K26: =G26+E26+I26 -> 0 | L26: =H26+F26+J26 -> 1542827186 | O26: 1542827186
A27: 건설기계대여대금지급보증서 | B27: 직접재료비,직접노무비,경비의 0.40% | C27: 1 | D27: 식 | F27: 0 | H27: 0 | J27: =TRUNC(((H18+F18+J18)*0.4/100),0) -> 608044310 | K27: =G27+E27+I27 -> 0 | L27: =H27+F27+J27 -> 608044310
A28: 산업안전보건관리비 | B28: 재료비,직접노무비의 1.38% | C28: 1 | D28: 식 | F28: 0 | H28: 0 | J28: =TRUNC(((H18+H19+F18)*1.38/100),0)*0+$O$28 -> 2027901531 | K28: =G28+E28+I28 -> 0 | L28: =H28+F28+J28 -> 2027901531 | O28: 2027901531
A29: 환 경 보 전 비 | B29: 직접재료비,직접노무비,경비의 0.6% | C29: 1 | D29: 식 | F29: 0 | H29: 0 | J29: =TRUNC(((H18+F18+J18)*0.6/100),0) -> 912066465 | K29: =G29+E29+I29 -> 0 | L29: =H29+F29+J29 -> 912066465
A30: 건설하도급대금지급보증서발급수수료 | B30: 직접재료비,직접노무비,경비의 0.071% | C30: 1 | D30: 식 | F30: 0 | H30: 0 | J30: =TRUNC(((H18+F18+J18)*0.071/100),0) -> 107927865 | K30: =G30+E30+I30 -> 0 | L30: =H30+F30+J30 -> 107927865
A31: 기 타 경 비 | B31: 재료비,노무비의 6.9% | C31: 1 | D31: 식 | F31: 0 | H31: 0 | J31: =TRUNC(((H18+H19+F18+F20)*6.9/100),0) -> 8961412121 | K31: =G31+E31+I31 -> 0 | L31: =H31+F31+J31 -> 8961412121
A32: 일 반 관 리 비 | B32: 순공사원가의 4.5% | C32: 1 | D32: 식 | F32: 0 | H32: 0 | J32: =TRUNC(((F18+H18+J18+F20+J21+J22+J23+J24+J25+J26+J27+J28+J29+J30+J31)*4.5/100),0) -> 8217526952 | K32: =G32+E32+I32 -> 0 | L32: =H32+F32+J32 -> 8217526952
A33: 피해방지대책비용 | B33: (순공사원가+일반관리비)×0.11% | C33: 1 | D33: 식 | F33: 0 | H33: 0 | J33: =TRUNC(((F18+H18+J18+F20+J21+J22+J23+J24+J25+J26+J27+J28+J29+J30+J31+J32)*0.11/100),0) -> 209912160 | K33: =G33+E33+I33 -> 0 | L33: =H33+F33+J33 -> 209912160
A34: 이 윤 | B34: 노무비,경비,일반관리비의 9% | C34: 1 | D34: 식 | F34: 0 | H34: 0 | J34: =TRUNC(((F18+J18+F20+J21+J22+J23+J24+J25+J26+J27+J28+J29+J30+J31+J32+J33)*9/100-594011/1.1),0) -> 11205848423 | K34: =G34+E34+I34 -> 0 | L34: =H34+F34+J34 -> 11205848423
A35: GIS측량성과비 | C35: 1 | D35: 식 | E35: 0 | G35: 0 | I35: 453609000 | J35: =TRUNC(I35*C35,0) -> 453609000 | K35: =G35+E35+I35 -> 453609000 | L35: =H35+F35+J35 -> 453609000
A36: 시공측량비 | C36: 21 | D36: km | E36: 0 | G36: 0 | I36: 6763000 | J36: =TRUNC(I36*C36,0) -> 142023000 | K36: =G36+E36+I36 -> 6763000 | L36: =H36+F36+J36 -> 142023000
A37: 폐기물처리용역 | C37: 1 | D37: 식 | E37: =F1806 -> 0 | G37: =H1806 -> -161747010 | H37: =TRUNC(G37*C37,0) -> -161747010 | I37: =J1806 -> 1274756603 | J37: =TRUNC(I37*C37,0) -> 1274756603 | K37: =G37+E37+I37 -> 1113009593 | L37: =H37+F37+J37 -> 1113009593
A38: 계측관리 | B38: 사면 | C38: 1 | D38: 식 | E38: 0 | G38: 0 | I38: 86639000 | J38: =TRUNC(I38*C38,0) -> 86639000 | K38: =G38+E38+I38 -> 86639000 | L38: =H38+F38+J38 -> 86639000
A39: 공 급 가 액 | B39: 순공사원가,일반관리비,이윤 | C39: 1 | D39: 식 | F39: 0 | H39: 0 | J39: =TRUNC((H18+J18+F18+F20+J21+J22+J23+J24+J25+J26+J27+J28+J29+J30+J31+J32+J33+J34+J35+J36+H37+J37+J38),0) -> 204040278182 | K39: =G39+E39+I39 -> 0 | L39: =H39+F39+J39 -> 204040278182
A40: 부 가 가 치 세 | B40: 총원가의 10% | C40: 1 | D40: 식 | F40: 0 | H40: 0 | J40: =TRUNC((J39*10/100),0) -> 20404027818 | K40: =G40+E40+I40 -> 0 | L40: =H40+F40+J40 -> 20404027818
...

Sheet 원가계산서(전기공사)
A2: 원 가 계 산 서 (전기)
A3: [공사명 : 진천 메가폴리스 산업단지 조성사업 전기공사]
A5: 구 분 | F5: 도 급 금 액 | G5: 비 고 | I5: 36개월 | K5: 50억미만
A6: 순 공 사 원 가 | B6: 재 료 비 | D6: 직 접 재 료 비 | F6: ='공종별집계표(전기공사)'!F6+'공종별집계표(전기공사)'!F15 -> 1972482406 | G6: 사급자재비 포함
D7: 간 접 재 료 비
D8: 소 계 | F8: =SUM(F6:F7) -> 1972482406
B9: 노 무 비 | D9: 직 접 노 무 비 | F9: ='공종별집계표(전기공사)'!H6 -> 1037484768
D10: 간 접 노 무 비 | F10: =TRUNC(($F$9)*G10%) -> 137985474 | G10: 13.3
D11: 소 계 | F11: =SUM(F9:F10) -> 1175470242
B12: 경 비 | D12: 산 출 경 비 | F12: ='공종별집계표(전기공사)'!J6 -> 22109916
D13: 산 재 보 험 료 | F13: =TRUNC(($F$11)*G13%) -> 41846740 | G13: 3.56
D14: 고 용 보 험 료 | F14: =TRUNC(($F$11)*G14%) -> 11872249 | G14: 1.01 | I14: 설계금액
D15: 건 강 보 험 료 | F15: =TRUNC(($F$9)*G15%)*0+$I$15 -> 44336163 | G15: 3.545 | I15: 44336163
D16: 연 금 보 험 료 | F16: =TRUNC(($F$9)*G16%)*0+$I$16 -> 56280038 | G16: 4.5 | I16: 56280038
D17: 퇴 직 공 제 부 금 비 | F17: =TRUNC(($F$9)*G17%)*0+$I$17 -> 28765353 | G17: 2.3 | I17: 28765353
D18: 노인장기요양보험료 | F18: =TRUNC(($F$15)*G18%)*0+$I$18 -> 5741533 | G18: 12.95 | I18: 5741533
D19: 산업안전보건관리비 | F19: =MIN(K19,K20)*0+I19 -> 86334499 | G19: 1.86 | I19: 86334499 | L19: 1.86
G20: 1.86 | K20: =TRUNC((((F8+F9)*G20%))*1.2+5349000) -> 72531467 | L20: 1.86
D21: 기 타 경 비 | F21: =TRUNC((F8+F11)*G21%) -> 223504638 | G21: 7.1
D22: 공사이행 보증수수료 | G22: 최저가 입찰대상공사(추정가격 300억원 이상)
D23: 환 경 보 전 비 | G23: 전기공사제외
D24: 소 계 | F24: =SUM(F12:F23) -> 520791129
A25: 합 계 | F25: =SUM(F8+F11+F24) -> 3668743777
B26: 일 반 관 리 비 | F26: =TRUNC(F25*G26%) -> 201780907 | G26: 5.5
B27: 이 윤 | F27: =TRUNC(((F11+F24+F26)*G27%))-INT(60128/1.1) -> 284651680 | G27: 15
B28: 공 급 가 액 | F28: =INT(SUM(F25,F26,F27)) -> 4155176364
B29: 부 가 가 치 세 | F29: =TRUNC(F28*0.1) -> 415517636
B30: 도 급 공 사 비 | F30: =SUM(F28:F29) -> 4570694000
B31: 도 급 자 관 급 자 재 비 | F31: =ROUNDDOWN(G31,-3) -> 0 | I31: 가로등, 공원등, 신호등
B32: 관 급 자 관 급 자 재 비 | F32: =ROUNDDOWN(G32,-3) -> 0 | I32: 그외
B33: 관 급 자 재 비 | F33: =F31+F32 -> 0
B34: 수 탁 비 | F34: =INT(G34/1000)*1000 -> 42000000 | G34: ='공종별집계표(전기공사)'!L23 -> 42000000 | I34: =F30/F11 -> 3.8883962
A35: 총 공 사 비 | F35: =SUM(F30+F33+F34) -> 4612694000 | G35: [ 2024년 공사원가계산 제비율, 50억~300억미만 , 13~36개월이하 적용 ]
F36: 4611851000 | G36: =F35-F36 -> 843000
F37: 0.852
F38: =F35/1.1 -> 4.1933582e+09

Sheet 공종별집계표(전기공사)
A1: 공 종 별 집 계 표
A2: [ 진천 메가폴리스 산업단지 조성사업 전기공사 ]
A3: 품 명 | B3: 규 격 | C3: 단위 | D3: 수량 | E3: 재 료 비 | G3: 노 무 비 | I3: 경 비 | K3: 합 계 | M3: 비 고 | N3: 공종코드 | O3: 변수 | P3: 상위공종 | Q3: 공종구분 | R3: 공종레벨 | S3: 공종소계 | T3: 원가계산서 연결금액
E4: 단 가 | F4: 금 액 | G4: 단 가 | H4: 금 액 | I4: 단 가 | J4: 금 액 | K4: 단 가 | L4: 금 액
A5: 진천 메가폴리스 일반산업단지 조성사업 전기공사 | D5: 1 | E5: =F6 -> 375822195 | F5: =E5*$D$7 -> 375822195 | G5: =H6 -> 1037484768 | H5: =G5*$D$7 -> 1037484768 | I5: =J6 -> 22109916 | J5: =I5*$D$7 -> 22109916 | K5: =E5+G5+I5 -> 1435416879 | L5: =F5+H5+J5 -> 1435416879 | N5: 01 | R5: 1
A6: 1. 전기공사 | D6: 1 | E6: =F7+F8+F9+F10+F13+F14 -> 375822195 | F6: =E6*$D$7 -> 375822195 | G6: =H7+H8+H9+H10+H13+H14 -> 1037484768 | H6: =G6*$D$7 -> 1037484768 | I6: =J7+J8+J9+J10+J13+J14 -> 22109916 | J6: =I6*$D$7 -> 22109916 | K6: =E6+G6+I6 -> 1435416879 | L6: =F6+H6+J6 -> 1435416879 | N6: 0101 | P6: 01 | R6: 2
A7: 1.1 가로등설비 | D7: 1 | E7: ='내역서(전기공사)'!F51 -> 161956615 | F7: =E7*$D$7 -> 161956615 | G7: ='내역서(전기공사)'!H51 -> 592547622 | H7: =G7*$D$7 -> 592547622 | I7: ='내역서(전기공사)'!J51 -> 10430435 | J7: =I7*$D$7 -> 10430435 | K7: =E7+G7+I7 -> 764934672 | L7: =F7+H7+J7 -> 764934672 | N7: 010101 | P7: 0101 | R7: 3
A8: 1.2 공원등설비 | D8: 1 | E8: ='내역서(전기공사)'!F75 -> 10127272 | F8: =E8*$D$7 -> 10127272 | G8: ='내역서(전기공사)'!H75 -> 36954861 | H8: =G8*$D$7 -> 36954861 | I8: ='내역서(전기공사)'!J75 -> 793615 | J8: =I8*$D$7 -> 793615 | K8: =E8+G8+I8 -> 47875748 | L8: =F8+H8+J8 -> 47875748 | N8: 010102 | P8: 0101 | R8: 3
A9: 1.3 신호등설비 | D9: 1 | E9: ='내역서(전기공사)'!F123 -> 153055512 | F9: =E9*$D$7 -> 153055512 | G9: ='내역서(전기공사)'!H123 -> 304464096 | H9: =G9*$D$7 -> 304464096 | I9: ='내역서(전기공사)'!J123 -> 9926186 | J9: =I9*$D$7 -> 9926186 | K9: =E9+G9+I9 -> 467445794 | L9: =F9+H9+J9 -> 467445794 | N9: 010103 | P9: 0101 | R9: 3
A10: 1.4 주차장 전기설비 | D10: 1 | E10: =F11+F12 -> 27401729 | F10: =E10*$D$7 -> 27401729 | G10: =H11+H12 -> 58350129 | H10: =G10*$D$7 -> 58350129 | I10: =J11+J12 -> 707445 | J10: =I10*$D$7 -> 707445 | K10: =E10+G10+I10 -> 86459303 | L10: =F10+H10+J10 -> 86459303 | N10: 010104 | P10: 0101 | R10: 3
A11: 1.4.1 주차장 전력간선설비 | D11: 1 | E11: ='내역서(전기공사)'!F147 -> 17832810 | F11: =E11*$D$7 -> 17832810 | G11: ='내역서(전기공사)'!H147 -> 25877659 | H11: =G11*$D$7 -> 25877659 | I11: ='내역서(전기공사)'!J147 -> 68502 | J11: =I11*$D$7 -> 68502 | K11: =E11+G11+I11 -> 43778971 | L11: =F11+H11+J11 -> 43778971 | N11: 01010401 | P11: 010104 | R11: 4
A12: 1.4.2 주차장 조명설비 | D12: 1 | E12: ='내역서(전기공사)'!F171 -> 9568919 | F12: =E12*$D$7 -> 9568919 | G12: ='내역서(전기공사)'!H171 -> 32472470 | H12: =G12*$D$7 -> 32472470 | I12: ='내역서(전기공사)'!J171 -> 638943 | J12: =I12*$D$7 -> 638943 | K12: =E12+G12+I12 -> 42680332 | L12: =F12+H12+J12 -> 42680332 | N12: 01010402 | P12: 010104 | R12: 4
A13: 1.5 교통신호제어기 온라인공사 | D13: 1 | E13: ='내역서(전기공사)'!F195 -> 19730141 | F13: =E13*$D$7 -> 19730141 | G13: ='내역서(전기공사)'!H195 -> 28559970 | H13: =G13*$D$7 -> 28559970 | I13: ='내역서(전기공사)'!J195 -> 79143 | J13: =I13*$D$7 -> 79143 | K13: =E13+G13+I13 -> 48369254 | L13: =F13+H13+J13 -> 48369254 | N13: 010105 | P13: 0101 | R13: 3
A14: 1.6 공원 CCTV설비 | D14: 1 | E14: ='내역서(전기공사)'!F219 -> 3550926 | F14: =E14*$D$7 -> 3550926 | G14: ='내역서(전기공사)'!H219 -> 16608090 | H14: =G14*$D$7 -> 16608090 | I14: ='내역서(전기공사)'!J219 -> 173092 | J14: =I14*$D$7 -> 173092 | K14: =E14+G14+I14 -> 20332108 | L14: =F14+H14+J14 -> 20332108 | N14: 010106 | P14: 0101 | R14: 3
A15: 2. 사급자재비 | D15: 1 | E15: =F16+F17+F18+F19+F22 -> 1596660211 | F15: =E15*$D$7 -> 1596660211 | G15: =H16+H17+H18+H19+H22 -> 0 | H15: =G15*$D$7 -> 0 | I15: =J16+J17+J18+J19+J22 -> 0 | J15: =I15*$D$7 -> 0 | K15: =E15+G15+I15 -> 1596660211 | L15: =F15+H15+J15 -> 1596660211 | N15: 0102 | Q15: 3 | R15: 2 | T15: =#REF!*1 -> #REF!
A16: 2.1 가로등설비 기자재비 | D16: 1 | E16: ='내역서(전기공사)'!F243 -> 875304679 | F16: =E16*$D$7 -> 875304679 | G16: ='내역서(전기공사)'!H243 -> 0 | H16: =G16*$D$7 -> 0 | I16: ='내역서(전기공사)'!J243 -> 0 | J16: =I16*$D$7 -> 0 | K16: =E16+G16+I16 -> 875304679 | L16: =F16+H16+J16 -> 875304679 | N16: 010201 | P16: 0102 | R16: 3
A17: 2.2 공원등설비 기자재비 | D17: 1 | E17: ='내역서(전기공사)'!F267 -> 53120839 | F17: =E17*$D$7 -> 53120839 | G17: ='내역서(전기공사)'!H267 -> 0 | H17: =G17*$D$7 -> 0 | I17: ='내역서(전기공사)'!J267 -> 0 | J17: =I17*$D$7 -> 0 | K17: =E17+G17+I17 -> 53120839 | L17: =F17+H17+J17 -> 53120839 | N17: 010202 | P17: 0102 | R17: 3
A18: 2.3 신호등설비 기자재비 | D18: 1 | E18: ='내역서(전기공사)'!F291 -> 395688210 | F18: =E18*$D$7 -> 395688210 | G18: ='내역서(전기공사)'!H291 -> 0 | H18: =G18*$D$7 -> 0 | I18: ='내역서(전기공사)'!J291 -> 0 | J18: =I18*$D$7 -> 0 | K18: =E18+G18+I18 -> 395688210 | L18: =F18+H18+J18 -> 395688210 | N18: 010203 | P18: 0102 | R18: 3
A19: 2.4 주차장 전기설비 기자재비 | D19: 1 | E19: =F20+F21 -> 135383239 | F19: =E19*$D$7 -> 135383239 | G19: =H20+H21 -> 0 | H19: =G19*$D$7 -> 0 | I19: =J20+J21 -> 0 | J19: =I19*$D$7 -> 0 | K19: =E19+G19+I19 -> 135383239 | L19: =F19+H19+J19 -> 135383239 | N19: 010204 | P19: 0102 | R19: 3
A20: 2.4.1 주차장 전력간선설비 기자재비 | D20: 1 | E20: ='내역서(전기공사)'!F315 -> 84156658 | F20: =E20*$D$7 -> 84156658 | G20: ='내역서(전기공사)'!H315 -> 0 | H20: =G20*$D$7 -> 0 | I20: ='내역서(전기공사)'!J315 -> 0 | J20: =I20*$D$7 -> 0 | K20: =E20+G20+I20 -> 84156658 | L20: =F20+H20+J20 -> 84156658 | N20: 01020401 | P20: 010204 | R20: 4
A21: 2.4.2 주차장 조명설비 기자재비 | D21: 1 | E21: ='내역서(전기공사)'!F339 -> 51226581 | F21: =E21*$D$7 -> 51226581 | G21: ='내역서(전기공사)'!H339 -> 0 | H21: =G21*$D$7 -> 0 | I21: ='내역서(전기공사)'!J339 -> 0 | J21: =I21*$D$7 -> 0 | K21: =E21+G21+I21 -> 51226581 | L21: =F21+H21+J21 -> 51226581 | N21: 01020402 | P21: 010204 | R21: 4
A22: 2.5 공원 CCTV설비 기자재비 | D22: 1 | E22: ='내역서(전기공사)'!F363 -> 137163244 | F22: =E22*$D$7 -> 137163244 | G22: ='내역서(전기공사)'!H363 -> 0 | H22: =G22*$D$7 -> 0 | I22: ='내역서(전기공사)'!J363 -> 0 | J22: =I22*$D$7 -> 0 | K22: =E22+G22+I22 -> 137163244 | L22: =F22+H22+J22 -> 137163244 | N22: 010205 | P22: 0102 | R22: 3
A23: 3. 수탁비 | D23: 1 | E23: ='내역서(전기공사)'!F387 -> 42000000 | F23: =E23*$D$7 -> 42000000 | G23: ='내역서(전기공사)'!G387 -> 0 | H23: =G23*$D$7 -> 0 | I23: ='내역서(전기공사)'!I387 -> 0 | J23: =I23*$D$7 -> 0 | K23: =E23+G23+I23 -> 42000000 | L23: =F23+H23+J23 -> 42000000 | N23: 0103 | Q23: 5 | R23: 2 | T23: =#REF!*1 -> #REF!
A27: [ 합 계 ] | F27: =F5 -> 375822195 | H27: =H5 -> 1037484768 | J27: =J5 -> 22109916 | L27: =L5 -> 1435416879

Sheet 내역서(전기공사)
A1: [ 진천 메가폴리스 산업단지 조성사업 전기공사 ]
A2: 품 명 | B2: 규 격 | C2: 단위 | D2: 수량 | E2: 재 료 비 | G2: 노 무 비 | I2: 경 비 | K2: 합 계 | M2: 비 고 | N2: 품목코드 | O2: 변수 | P2: 설정 | Q2: 공종코드 | R2: 일위 | S2: 단산 | T2: 자재 | U2: 손료적용 | V2: 손료저장 | W2: 적용율 | X2: JUK1 | Y2: JUK2 | Z2: JUK3 | AA2: JUK4 | AB2: JUK5 | AC2: JUK6 | AD2: JUK7 | AE2: JUK8 | AF2: JUK9 | AG2: JUK10 | AH2: JUK11 | AI2: JUK12 | AJ2: JUK13 | AK2: JUK14 | AL2: JUK15 | AM2: JUK16 | AN2: JUK17 | AO2: JUK18 | AP2: JUK19 | AQ2: JUK20 | AR2: 자재구분 | AS2: 공종구분 | AT2: 공종레벨 | AU2: 공종+자재 | AV2: 고유번호
E3: 단 가 | F3: 금 액 | G3: 단 가 | H3: 금 액 | I3: 단 가 | J3: 금 액 | K3: 단 가 | L3: 금 액
A4: 1.1 가로등설비 | Q4: 010101
A5: 폴리에틸렌 전선관-지중매입 가로/신호등 | B5: PE 28㎜ | C5: M | D5: 1811 | E5: 925 | F5: =TRUNC(E5*D5, 0) -> 1675175 | G5: 12786 | H5: =TRUNC(G5*D5, 0) -> 23155446 | I5: 0 | J5: =TRUNC(I5*D5, 0) -> 0 | K5: =TRUNC(E5+G5+I5, 0) -> 13711 | L5: =TRUNC(F5+H5+J5, 0) -> 24830621 | M5: 호표 45 | N5: 53A91303286374986FE7050F73DB0C | Q5: 010101 | R5: T | S5: F | T5: F | AU5: 01010153A91303286374986FE7050F73DB0C | AV5: 19173
A6: 폴리에틸렌 전선관-지중매입 가로/신호등 | B6: PE 36㎜ | C6: M | D6: 12537 | E6: 1212 | F6: =TRUNC(E6*D6, 0) -> 15194844 | G6: 12786 | H6: =TRUNC(G6*D6, 0) -> 160298082 | I6: 0 | J6: =TRUNC(I6*D6, 0) -> 0 | K6: =TRUNC(E6+G6+I6, 0) -> 13998 | L6: =TRUNC(F6+H6+J6, 0) -> 175492926 | M6: 호표 46 | N6: 53A91303286374986FE7050F73DA65 | Q6: 010101 | R6: T | S6: F | T6: F | AU6: 01010153A91303286374986FE7050F73DA65 | AV6: 11207
A7: 폴리에틸렌 전선관-지중매입 가로/신호등 | B7: PE 42㎜ | C7: M | D7: 1435 | E7: 1359 | F7: =TRUNC(E7*D7, 0) -> 1950165 | G7: 14672 | H7: =TRUNC(G7*D7, 0) -> 21054320 | I7: 0 | J7: =TRUNC(I7*D7, 0) -> 0 | K7: =TRUNC(E7+G7+I7, 0) -> 16031 | L7: =TRUNC(F7+H7+J7, 0) -> 23004485 | M7: 호표 47 | N7: 53A91303286374986FE7050F73D95E | Q7: 010101 | R7: T | S7: F | T7: F | AU7: 01010153A91303286374986FE7050F73D95E | AV7: 20591
A8: 폴리에틸렌 전선관-지중매입 가로/신호등 | B8: PE 100㎜ | C8: M | D8: 351 | E8: 5489 | F8: =TRUNC(E8*D8, 0) -> 1926639 | G8: 19902 | H8: =TRUNC(G8*D8, 0) -> 6985602 | I8: 0 | J8: =TRUNC(I8*D8, 0) -> 0 | K8: =TRUNC(E8+G8+I8, 0) -> 25391 | L8: =TRUNC(F8+H8+J8, 0) -> 8912241 | M8: 호표 51 | N8: 53A91303286374986FE7050F7238BE | Q8: 010101 | R8: T | S8: F | T8: F | AU8: 01010153A91303286374986FE7050F7238BE | AV8: 19175
A9: 0.6/1kV 난연 전력 케이블(F-CV)-등주내배선 | B9: 2C 2.5㎟ | C9: m | D9: 4009 | E9: 1278 | F9: =TRUNC(E9*D9, 0) -> 5123502 | G9: 2448 | H9: =TRUNC(G9*D9, 0) -> 9814032 | I9: 0 | J9: =TRUNC(I9*D9, 0) -> 0 | K9: =TRUNC(E9+G9+I9, 0) -> 3726 | L9: =TRUNC(F9+H9+J9, 0) -> 14937534 | M9: 호표 62 | N9: 53A91303286146836D538707D24684 | Q9: 010101 | R9: T | S9: F | T9: F | AU9: 01010153A91303286146836D538707D24684 | AV9: 20303
A10: 0.6/1kV 난연 전력 케이블(F-CV)-2열가로/신호등 | B10: 1C 6㎟ | C10: m | D10: 3746 | E10: 1020 | F10: =TRUNC(E10*D10, 0) -> 3820920 | G10: 2372 | H10: =TRUNC(G10*D10, 0) -> 8885512 | I10: 0 | J10: =TRUNC(I10*D10, 0) -> 0 | K10: =TRUNC(E10+G10+I10, 0) -> 3392 | L10: =TRUNC(F10+H10+J10, 0) -> 12706432 | M10: 호표 58 | N10: 53A91303286146836D53BC0EA53FC4 | Q10: 010101 | R10: T | S10: F | T10: F | AU10: 01010153A91303286146836D53BC0EA53FC4 | AV10: 11211
A11: 0.6/1kV 난연 전력 케이블(F-CV)-4열가로/신호등 | B11: 1C 6㎟ | C11: m | D11: 49724 | E11: 1016 | F11: =TRUNC(E11*D11, 0) -> 50519584 | G11: 2219 | H11: =TRUNC(G11*D11, 0) -> 110337556 | I11: 0 | J11: =TRUNC(I11*D11, 0) -> 0 | K11: =TRUNC(E11+G11+I11, 0) -> 3235 | L11: =TRUNC(F11+H11+J11, 0) -> 160857140 | M11: 호표 60 | N11: 53A91303286146836D53BC0D9ECEB3 | Q11: 010101 | R11: T | S11: F | T11: F | AU11: 01010153A91303286146836D53BC0D9ECEB3 | AV11: 11212
A12: 0.6/1kV 난연 전력 케이블(F-CV)-4열가로/신호등 | B12: 1C 10㎟ | C12: m | D12: 5580 | E12: 1596 | F12: =TRUNC(E12*D12, 0) -> 8905680 | G12: 2334 | H12: =TRUNC(G12*D12, 0) -> 13023720 | I12: 0 | J12: =TRUNC(I12*D12, 0) -> 0 | K12: =TRUNC(E12+G12+I12, 0) -> 3930 | L12: =TRUNC(F12+H12+J12, 0) -> 21929400 | M12: 호표 61 | N12: 53A91303286146836D53BC0D9ECF5A | Q12: 010101 | R12: T | S12: F | T12: F | AU12: 01010153A91303286146836D53BC0D9ECF5A | AV12: 20592
A13: 0.6/1kV 난연 전력 케이블(F-CV)-가로/신호등 | B13: 2C 16㎟ | C13: m | D13: 810 | E13: 4964 | F13: =TRUNC(E13*D13, 0) -> 4020840 | G13: 4209 | H13: =TRUNC(G13*D13, 0) -> 3409290 | I13: 0 | J13: =TRUNC(I13*D13, 0) -> 0 | K13: =TRUNC(E13+G13+I13, 0) -> 9173 | L13: =TRUNC(F13+H13+J13, 0) -> 7430130 | M13: 호표 64 | N13: 53A91303286146836D5387041ED84D | Q13: 010101 | R13: T | S13: F | T13: F | AU13: 01010153A91303286146836D5387041ED84D | AV13: 20460
A14: 0.6/1kV 난연 전력 케이블(F-CV)-가로/신호등 | B14: 2C 25㎟ | C14: m | D14: 108 | E14: 8148 | F14: =TRUNC(E14*D14, 0) -> 879984 | G14: 4859 | H14: =TRUNC(G14*D14, 0) -> 524772 | I14: 0 | J14: =TRUNC(I14*D14, 0) -> 0 | K14: =TRUNC(E14+G14+I14, 0) -> 13007 | L14: =TRUNC(F14+H14+J14, 0) -> 1404756 | M14: 호표 65 | N14: 53A91303286146836D5387041ED954 | Q14: 010101 | R14: T | S14: F | T14: F | AU14: 01010153A91303286146836D5387041ED954 | AV14: 20593
A15: 난연 비닐 절연 접지용전선(F-GV) | B15: 0.6/1kV 6㎟ | C15: m | D15: 15699 | E15: 836 | F15: =TRUNC(E15*D15, 0) -> 13124364 | G15: 1344 | H15: =TRUNC(G15*D15, 0) -> 21099456 | I15: 0 | J15: =TRUNC(I15*D15, 0) -> 0 | K15: =TRUNC(E15+G15+I15, 0) -> 2180 | L15: =TRUNC(F15+H15+J15, 0) -> 34223820 | M15: 호표 52 | N15: 53A913032860A03F6C74A20C8B1E1B | Q15: 010101 | R15: T | S15: F | T15: F | AU15: 01010153A913032860A03F6C74A20C8B1E1B | AV15: 20130
A16: 터미널 | B16: 압착단자, 터미널, 16㎟ | C16: 개 | D16: 60 | E16: 649 | F16: =TRUNC(E16*D16, 0) -> 38940 | G16: 18159 | H16: =TRUNC(G16*D16, 0) -> 1089540 | I16: 0 | J16: =TRUNC(I16*D16, 0) -> 0 | K16: =TRUNC(E16+G16+I16, 0) -> 18808 | L16: =TRUNC(F16+H16+J16, 0) -> 1128480 | M16: 호표 85 | N16: 53A91303286B4AD36052AE0839886A | Q16: 010101 | R16: T | S16: F | T16: F | AU16: 01010153A91303286B4AD36052AE0839886A | AV16: 11222
... A33: 방수형 접속함 | B33: ELB 방수형 | C33: 개 | D33: 421 | E33: 46522 | F33: =TRUNC(E33*D33, 0) -> 19585762 | G33: 29818 | H33: =TRUNC(G33*D33, 0) -> 12553378 | I33: 0 | J33: =TRUNC(I33*D33, 0) -> 0 | K33: =TRUNC(E33+G33+I33, 0) -> 76340 | L33: =TRUNC(F33+H33+J33, 0) -> 32139140 | M33: 호표 37 | N33: 53A9130328626DAA682769037AA911 | Q33: 010101 | R33: T | S33: F | T33: F | AU33: 01010153A9130328626DAA682769037AA911 | AV33: 11235
A34: 방수형 접속함 | B34: BY-PASS용 | C34: 개 | D34: 369 | E34: 12444 | F34: =TRUNC(E34*D34, 0) -> 4591836 | G34: 0 | H34: =TRUNC(G34*D34, 0) -> 0 | I34: 0 | J34: =TRUNC(I34*D34, 0) -> 0 | K34: =TRUNC(E34+G34+I34, 0) -> 12444 | L34: =TRUNC(F34+H34+J34, 0) -> 4591836 | N34: 54C3432D206059FB6015D20D6D8D83753D2032 | Q34: 010101 | R34: F | S34: F | T34: T | AU34: 01010154C3432D206059FB6015D20D6D8D83753D2032 | AV34: 11236
A35: 한전인입 | B35: 저압 | C35: EA | D35: 17 | E35: 137695 | F35: =TRUNC(E35*D35, 0) -> 2340815 | G35: 644059 | H35: =TRUNC(G35*D35, 0) -> 10949003 | I35: 0 | J35: =TRUNC(I35*D35, 0) -> 0 | K35: =TRUNC(E35+G35+I35, 0) -> 781754 | L35: =TRUNC(F35+H35+J35, 0) -> 13289818 | M35: 호표 24 | N35: 53A9130328626DA86D49EC0647538E | Q35: 010101 | R35: T | S35: F | T35: F | AU35: 01010153A9130328626DA86D49EC0647538E | AV35: 20070
A51: [ 합 계 ] | F51: =SUM(F5:F50) -> 161956615 | H51: =SUM(H5:H50) -> 592547622 | J51: =SUM(J5:J50) -> 10430435 | L51: =SUM(L5:L50) -> 764934672 | N51: TOTAL
A52: 1.2 공원등설비 | Q52: 010102
A53: 폴리에틸렌 전선관-지중매입 가로/신호등 | B53: PE 28㎜ | C53: M | D53: 191 | E53: 925 | F53: =TRUNC(E53*D53, 0) -> 176675 | G53: 12786 | H53: =TRUNC(G53*D53, 0) -> 2442126 | I53: 0 | J53: =TRUNC(I53*D53, 0) -> 0 | K53: =TRUNC(E53+G53+I53, 0) -> 13711 | L53: =TRUNC(F53+H53+J53, 0) -> 2618801 | M53: 호표 45 | N53: 53A91303286374986FE7050F73DB0C | Q53: 010102 | R53: T | S53: F | T53: F | AU53: 01010253A91303286374986FE7050F73DB0C | AV53: 19399
A54: 폴리에틸렌 전선관-지중매입 가로/신호등 | B54: PE 36㎜ | C54: M | D54: 733 | E54: 1212 | F54: =TRUNC(E54*D54, 0) -> 888396 | G54: 12786 | H54: =TRUNC(G54*D54, 0) -> 9372138 | I54: 0 | J54: =TRUNC(I54*D54, 0) -> 0 | K54: =TRUNC(E54+G54+I54, 0) -> 13998 | L54: =TRUNC(F54+H54+J54, 0) -> 10260534 | M54: 호표 46 | N54: 53A91303286374986FE7050F73DA65 | Q54: 010102 | R54: T | S54: F | T54: F | AU54: 01010253A91303286374986FE7050F73DA65 | AV54: 19371
A55: 0.6/1kV 난연 전력 케이블(F-CV)-등주내배선 | B55: 2C 2.5㎟ | C55: m | D55: 193 | E55: 1278 | F55: =TRUNC(E55*D55, 0) -> 246654 | G55: 2448 | H55: =TRUNC(G55*D55, 0) -> 472464 | I55: 0 | J55: =TRUNC(I55*D55, 0) -> 0 | K55: =TRUNC(E55+G55+I55, 0) -> 3726 | L55: =TRUNC(F55+H55+J55, 0) -> 719118 | M55: 호표 62 | N55: 53A91303286146836D538707D24684 | Q55: 010102 | R55: T | S55: F | T55: F | AU55: 01010253A91303286146836D538707D24684 | AV55: 20305
A56: 0.6/1kV 난연 전력 케이블(F-CV)-2열가로/신호등 | B56: 1C 6㎟ | C56: m | D56: 414 | E56: 1020 | F56: =TRUNC(E56*D56, 0) -> 422280 | G56: 2372 | H56: =TRUNC(G56*D56, 0) -> 982008 | I56: 0 | J56: =TRUNC(I56*D56, 0) -> 0 | K56: =TRUNC(E56+G56+I56, 0) -> 3392 | L56: =TRUNC(F56+H56+J56, 0) -> 1404288 | M56: 호표 58 | N56: 53A91303286146836D53BC0EA53FC4 | Q56: 010102 | R56: T | S56: F | T56: F | AU56: 01010253A91303286146836D53BC0EA53FC4 | AV56: 19373
A57: 0.6/1kV 난연 전력 케이블(F-CV)-4열가로/신호등 | B57: 1C 6㎟ | C57: m | D57: 2740 | E57: 1016 | F57: =TRUNC(E57*D57, 0) -> 2783840 | G57: 2219 | H57: =TRUNC(G57*D57, 0) -> 6080060 | I57: 0 | J57: =TRUNC(I57*D57, 0) -> 0 | K57: =TRUNC(E57+G57+I57, 0) -> 3235 | L57: =TRUNC(F57+H57+J57, 0) -> 8863900 | M57: 호표 60 | N57: 53A91303286146836D53BC0D9ECEB3 | Q57: 010102 | R57: T | S57: F | T57: F | AU57: 01010253A91303286146836D53BC0D9ECEB3 | AV57: 19374
A58: 0.6/1kV 난연 전력 케이블(F-CV)-2열가로/신호등 | B58: 1C 16㎟ | C58: m | D58: 108 | E58: 2431 | F58: =TRUNC(E58*D58, 0) -> 262548 | G58: 2716 | H58: =TRUNC(G58*D58, 0) -> 293328 | I58: 0 | J58: =TRUNC(I58*D58, 0) -> 0 | K58: =TRUNC(E58+G58+I58, 0) -> 5147 | L58: =TRUNC(F58+H58+J58, 0) -> 555876 | M58: 호표 59 | N58: 53A91303286146836D53BC0EA53D17 | Q58: 010102 | R58: T | S58: F | T58: F | AU58: 01010253A91303286146836D53BC0EA53D17 | AV58: 20082
A59: 난연 비닐 절연 접지용전선(F-GV) | B59: 0.6/1kV 6㎟ | C59: m | D59: 892 | E59: 836 | F59: =TRUNC(E59*D59, 0) -> 745712 | G59: 1344 | H59: =TRUNC(G59*D59, 0) -> 1198848 | I59: 0 | J59: =TRUNC(I59*D59, 0) -> 0 | K59: =TRUNC(E59+G59+I59, 0) -> 2180 | L59: =TRUNC(F59+H59+J59, 0) -> 1944560 | M59: 호표 52 | N59: 53A913032860A03F6C74A20C8B1E1B | Q59: 010102 | R59: T | S59: F | T59: F | AU59: 01010253A913032860A03F6C74A20C8B1E1B | AV59: 20131
A60: 터미널 | B60: 압착단자, 터미널, 16㎟ | C60: 개 | D60: 8 | E60: 649 | F60: =TRUNC(E60*D60, 0) -> 5192 | G60: 18159 | H60: =TRUNC(G60*D60, 0) -> 145272 | I60: 0 | J60: =TRUNC(I60*D60, 0) -> 0 | K60: =TRUNC(E60+G60+I60, 0) -> 18808 | L60: =TRUNC(F60+H60+J60, 0) -> 150464 | M60: 호표 85 | N60: 53A91303286B4AD36052AE0839886A | Q60: 010102 | R60: T | S60: F | T60: F | AU60: 01010253A91303286B4AD36052AE0839886A | AV60: 19378
A61: 공원등주 설치 | B61: 5M 1등용 | C61: 개소 | D61: 35 | E61: 5832 | F61: =TRUNC(E61*D61, 0) -> 204120 | G61: 103525 | H61: =TRUNC(G61*D61, 0) -> 3623375 | I61: 6319 | J61: =TRUNC(I61*D61, 0) -> 221165 | K61: =TRUNC(E61+G61+I61, 0) -> 115676 | L61: =TRUNC(F61+H61+J61, 0) -> 4048660 | M61: 호표 29 | N61: 53A9130328626DAA68276903798163 | Q61: 010102 | R61: T | S61: F | T61: F | AU61: 01010253A9130328626DAA68276903798163 | AV61: 20072
A62: 공원등기구 설치 | B62: LED 50W | C62: EA | D62: 35 | E62: 1230 | F62: =TRUNC(E62*D62, 0) -> 43050 | G62: 41027 | H62: =TRUNC(G62*D62, 0) -> 1435945 | I62: 0 | J62: =TRUNC(I62*D62, 0) -> 0 | K62: =TRUNC(E62+G62+I62, 0) -> 42257 | L62: =TRUNC(F62+H62+J62, 0) -> 1478995 | M62: 호표 35 | N62: 53A9130328626DAA6827690378FF18 | Q62: 010102 | R62: T | S62: F | T62: F | AU62: 01010253A9130328626DAA6827690378FF18 | AV62: 20075
A63: 공원등기초(5m) | B63: 직각형(500*675*850*700) | C63: 개소 | D63: 35 | E63: 9374 | F63: =TRUNC(E63*D63, 0) -> 328090 | G63: 74534 | H63: =TRUNC(G63*D63, 0) -> 2608690 | I63: 11266 | J63: =TRUNC(I63*D63, 0) -> 394310 | K63: =TRUNC(E63+G63+I63, 0) -> 95174 | L63: =TRUNC(F63+H63+J63, 0) -> 3331090 | M63: 호표 19 | N63: 53A9130328626DA86D49FE0D513F8E | Q63: 010102 | R63: T | S63: F | T63: F | AU63: 01010253A9130328626DA86D49FE0D513F8E | AV63: 20454
A64: 분전반 설치 | B64: 4회로 | C64: 개소 | D64: 2 | E64: 13726 | F64: =TRUNC(E64*D64, 0) -> 27452 | G64: 457561 | H64: =TRUNC(G64*D64, 0) -> 915122 | I64: 0 | J64: =TRUNC(I64*D64, 0) -> 0 | K64: =TRUNC(E64+G64+I64, 0) -> 471287 | L64: =TRUNC(F64+H64+J64, 0) -> 942574 | M64: 호표 25 | N64: 53A9130328626DAB6A87B30846F9AE | Q64: 010102 | R64: T | S64: F | T64: F | AU64: 01010253A9130328626DAB6A87B30846F9AE | AV64: 20329
... A71: 방수형 접속함 | B71: ELB 방수형 | C71: 개 | D71: 35 | E71: 46522 | F71: =TRUNC(E71*D71, 0) -> 1628270 | G71: 29818 | H71: =TRUNC(G71*D71, 0) -> 1043630 | I71: 0 | J71: =TRUNC(I71*D71, 0) -> 0 | K71: =TRUNC(E71+G71+I71, 0) -> 76340 | L71: =TRUNC(F71+H71+J71, 0) -> 2671900 | M71: 호표 37 | N71: 53A9130328626DAA682769037AA911 | Q71: 010102 | R71: T | S71: F | T71: F | AU71: 01010253A9130328626DAA682769037AA911 | AV71: 19384
A72: 방수형 접속함 | B72: BY-PASS용 | C72: 개 | D72: 27 | E72: 12444 | F72: =TRUNC(E72*D72, 0) -> 335988 | G72: 0 | H72: =TRUNC(G72*D72, 0) -> 0 | I72: 0 | J72: =TRUNC(I72*D72, 0) -> 0 | K72: =TRUNC(E72+G72+I72, 0) -> 12444 | L72: =TRUNC(F72+H72+J72, 0) -> 335988 | N72: 54C3432D206059FB6015D20D6D8D83753D2032 | Q72: 010102 | R72: F | S72: F | T72: T | AU72: 01010254C3432D206059FB6015D20D6D8D83753D2032 | AV72: 19385
A73: 한전인입 | B73: 저압 | C73: EA | D73: 2 | E73: 137695 | F73: =TRUNC(E73*D73, 0) -> 275390 | G73: 644059 | H73: =TRUNC(G73*D73, 0) -> 1288118 | I73: 0 | J73: =TRUNC(I73*D73, 0) -> 0 | K73: =TRUNC(E73+G73+I73, 0) -> 781754 | L73: =TRUNC(F73+H73+J73, 0) -> 1563508 | M73: 호표 24 | N73: 53A9130328626DA86D49EC0647538E | Q73: 010102 | R73: T | S73: F | T73: F | AU73: 01010253A9130328626DA86D49EC0647538E | AV73: 20078
A75: [ 합 계 ] | F75: =SUM(F53:F74) -> 10127272 | H75: =SUM(H53:H74) -> 36954861 | J75: =SUM(J53:J74) -> 793615 | L75: =SUM(L53:L74) -> 47875748 | N75: TOTAL
A76: 1.3 신호등설비 | Q76: 010103
A77: 폴리에틸렌 전선관-지중매입 가로/신호등 | B77: PE 28㎜ | C77: M | D77: 1695 | E77: 925 | F77: =TRUNC(E77*D77, 0) -> 1567875 | G77: 12786 | H77: =TRUNC(G77*D77, 0) -> 21672270 | I77: 0 | J77: =TRUNC(I77*D77, 0) -> 0 | K77: =TRUNC(E77+G77+I77, 0) -> 13711 | L77: =TRUNC(F77+H77+J77, 0) -> 23240145 | M77: 호표 45 | N77: 53A91303286374986FE7050F73DB0C | Q77: 010103 | R77: T | S77: F | T77: F | AU77: 01010353A91303286374986FE7050F73DB0C | AV77: 19417
A78: 폴리에틸렌 전선관-지중매입 가로/신호등 | B78: PE 36㎜ | C78: M | D78: 1004 | E78: 1212 | F78: =TRUNC(E78*D78, 0) -> 1216848 | G78: 12786 | H78: =TRUNC(G78*D78, 0) -> 12837144 | I78: 0 | J78: =TRUNC(I78*D78, 0) -> 0 | K78: =TRUNC(E78+G78+I78, 0) -> 13998 | L78: =TRUNC(F78+H78+J78, 0) -> 14053992 | M78: 호표 46 | N78: 53A91303286374986FE7050F73DA65 | Q78: 010103 | R78: T | S78: F | T78: F | AU78: 01010353A91303286374986FE7050F73DA65 | AV78: 19207
...

Sheet Sheet4
C17: 전 기 공 사
